2024-11-19 07:09:11,308 INFO django.utils.autoreload Watching for file changes with StatReloader
2024-11-19 08:51:30,993 INFO django.utils.autoreload Watching for file changes with StatReloader
2024-11-19 08:52:12,178 ERROR django.server "GET / HTTP/1.1" 500 59
2024-11-19 08:52:12,550 ERROR django.server "GET /favicon.ico HTTP/1.1" 500 59
2024-11-19 08:55:02,591 INFO django.utils.autoreload Watching for file changes with StatReloader
2024-11-19 08:55:20,441 ERROR django.server "GET / HTTP/1.1" 500 59
2024-11-19 08:55:20,799 ERROR django.server "GET /favicon.ico HTTP/1.1" 500 59
2024-11-19 09:06:25,399 INFO django.utils.autoreload Watching for file changes with StatReloader
2024-11-19 09:06:35,825 WARNING django.request Not Found: /
2024-11-19 09:06:35,826 WARNING django.server "GET / HTTP/1.1" 404 2928
2024-11-19 09:06:53,841 INFO django.server "GET /api HTTP/1.1" 301 0
2024-11-19 09:06:53,867 WARNING django.request Unauthorized: /api/
2024-11-19 09:06:53,868 WARNING django.server "GET /api/ HTTP/1.1" 401 5019
2024-11-19 09:06:53,923 INFO django.server "GET /static/rest_framework/css/bootstrap-tweaks.css HTTP/1.1" 200 3385
2024-11-19 09:06:53,923 INFO django.server "GET /static/rest_framework/css/default.css HTTP/1.1" 200 1152
2024-11-19 09:06:53,924 INFO django.server "GET /static/rest_framework/css/prettify.css HTTP/1.1" 200 817
2024-11-19 09:06:53,927 INFO django.server "GET /static/rest_framework/js/ajax-form.js HTTP/1.1" 200 3597
2024-11-19 09:06:53,927 INFO django.server "GET /static/rest_framework/js/csrf.js HTTP/1.1" 200 1719
2024-11-19 09:06:53,929 INFO django.server "GET /static/rest_framework/js/prettify-min.js HTTP/1.1" 200 13632
2024-11-19 09:06:53,930 INFO django.server "GET /static/rest_framework/js/bootstrap.min.js HTTP/1.1" 200 39680
2024-11-19 09:06:53,931 INFO django.server "GET /static/rest_framework/js/default.js HTTP/1.1" 200 1268
2024-11-19 09:06:53,931 INFO django.server "GET /static/rest_framework/css/bootstrap.min.css HTTP/1.1" 200 121457
2024-11-19 09:06:53,932 INFO django.server "GET /static/rest_framework/js/jquery-3.5.1.min.js HTTP/1.1" 200 89476
2024-11-19 09:06:53,945 INFO django.server "GET /static/rest_framework/img/grid.png HTTP/1.1" 200 1458
2024-11-19 09:06:57,305 WARNING django.request Not Found: /
2024-11-19 09:06:57,306 WARNING django.server "GET / HTTP/1.1" 404 2928
2024-11-19 09:07:01,913 INFO django.server "GET /admin/ HTTP/1.1" 302 0
2024-11-19 09:07:01,937 INFO django.server "GET /admin/login/?next=/admin/ HTTP/1.1" 200 4158
2024-11-19 09:07:01,977 INFO django.server "GET /static/admin/css/base.css HTTP/1.1" 200 21544
2024-11-19 09:07:01,983 INFO django.server "GET /static/admin/css/dark_mode.css HTTP/1.1" 200 2682
2024-11-19 09:07:01,984 INFO django.server "GET /static/admin/css/login.css HTTP/1.1" 200 958
2024-11-19 09:07:01,985 INFO django.server "GET /static/admin/js/nav_sidebar.js HTTP/1.1" 200 3063
2024-11-19 09:07:01,985 INFO django.server "GET /static/admin/js/theme.js HTTP/1.1" 200 1943
2024-11-19 09:07:01,986 INFO django.server "GET /static/admin/css/nav_sidebar.css HTTP/1.1" 200 2810
2024-11-19 09:07:01,987 INFO django.server "GET /static/admin/css/responsive.css HTTP/1.1" 200 17905
2024-11-19 09:07:08,836 INFO django.server "POST /admin/login/?next=/admin/ HTTP/1.1" 200 4319
2024-11-19 09:07:11,368 INFO django.server "GET /admin/login/?next=/admin/ HTTP/1.1" 200 4158
2024-11-19 09:07:14,982 WARNING django.request Not Found: /
2024-11-19 09:07:14,982 WARNING django.server "GET / HTTP/1.1" 404 2928
2024-11-19 09:08:04,884 WARNING django.request Method Not Allowed: /register/
2024-11-19 09:08:04,884 WARNING django.server "GET /register/ HTTP/1.1" 405 5599
2024-11-19 09:08:07,793 INFO django.server "GET /register HTTP/1.1" 301 0
2024-11-19 09:08:07,809 WARNING django.request Method Not Allowed: /register/
2024-11-19 09:08:07,810 WARNING django.server "GET /register/ HTTP/1.1" 405 5599
2024-11-19 09:08:14,267 WARNING django.request Not Found: /
2024-11-19 09:08:14,267 WARNING django.server "GET / HTTP/1.1" 404 2928
2024-11-19 09:08:21,545 WARNING django.request Method Not Allowed: /login/
2024-11-19 09:08:21,546 WARNING django.server "GET /login/ HTTP/1.1" 405 5582
2024-11-19 09:08:24,061 INFO django.server "GET /login HTTP/1.1" 301 0
2024-11-19 09:08:24,075 WARNING django.request Method Not Allowed: /login/
2024-11-19 09:08:24,076 WARNING django.server "GET /login/ HTTP/1.1" 405 5582
2024-11-19 09:08:24,140 WARNING django.request Not Found: /favicon.ico
2024-11-19 09:08:24,140 WARNING django.server "GET /favicon.ico HTTP/1.1" 404 2979
2024-11-19 09:08:38,543 WARNING django.request Not Found: /
2024-11-19 09:08:38,544 WARNING django.server "GET / HTTP/1.1" 404 2928
2024-11-19 09:08:52,169 WARNING django.request Not Found: /
2024-11-19 09:08:52,170 WARNING django.server "GET / HTTP/1.1" 404 2928
2024-11-19 09:08:52,236 WARNING django.request Not Found: /favicon.ico
2024-11-19 09:08:52,237 WARNING django.server "GET /favicon.ico HTTP/1.1" 404 2979
2024-11-19 09:08:52,858 WARNING django.request Not Found: /
2024-11-19 09:08:52,859 WARNING django.server "GET / HTTP/1.1" 404 2928
2024-11-19 09:09:04,390 WARNING django.request Unauthorized: /api/
2024-11-19 09:09:04,390 WARNING django.server "GET /api/ HTTP/1.1" 401 5019
2024-11-19 09:09:04,451 INFO django.server "GET /static/rest_framework/img/grid.png HTTP/1.1" 200 1458
2024-11-19 09:10:16,474 INFO django.server code 400, message Bad request version ('³')
2024-11-19 09:10:16,475 ERROR django.server You're accessing the development server over HTTPS, but it only supports HTTP.
2024-11-19 09:10:16,476 INFO django.server code 400, message Bad request version (';Ò\x19XÔ·=C±\x84»^¯I«?@¿Ý\x13¿,\x96åFöNtID;\x9c\x00"\x13\x01\x13\x03\x13\x02À+À/Ì©Ì¨À,À0À')
2024-11-19 09:10:16,477 ERROR django.server You're accessing the development server over HTTPS, but it only supports HTTP.
2024-11-19 09:10:17,919 INFO django.server code 400, message Bad request version ('\x02\x10Ò\x00"\x13\x01\x13\x03\x13\x02À+À/Ì©Ì¨À,À0À')
2024-11-19 09:10:17,919 ERROR django.server You're accessing the development server over HTTPS, but it only supports HTTP.
2024-11-19 09:10:17,920 INFO django.server code 400, message Bad request version ('é¦\x93\x9bJàÐP¬\x95\x9eÕ\x00"\x13\x01\x13\x03\x13\x02À+À/Ì©Ì¨À,À0À')
2024-11-19 09:10:17,921 ERROR django.server You're accessing the development server over HTTPS, but it only supports HTTP.
2024-11-19 09:12:22,576 WARNING django.request Method Not Allowed: /login/
2024-11-19 09:12:22,577 WARNING django.server "GET /login/ HTTP/1.1" 405 5582
2024-11-19 09:12:26,731 INFO django.server "GET /admin/ HTTP/1.1" 302 0
2024-11-19 09:12:26,743 INFO django.server "GET /admin/login/?next=/admin/ HTTP/1.1" 200 4158
2024-11-19 09:12:30,143 INFO django.server "POST /admin/login/?next=/admin/ HTTP/1.1" 302 0
2024-11-19 09:12:30,168 INFO django.server "GET /admin/ HTTP/1.1" 200 6427
2024-11-19 09:12:30,212 INFO django.server "GET /static/admin/css/dashboard.css HTTP/1.1" 200 441
2024-11-19 09:12:30,237 INFO django.server "GET /static/admin/img/icon-addlink.svg HTTP/1.1" 200 331
2024-11-19 09:12:30,237 INFO django.server "GET /static/admin/img/icon-changelink.svg HTTP/1.1" 200 380
2024-11-19 09:12:34,231 INFO django.server "GET /admin/accounts/ HTTP/1.1" 200 5048
2024-11-19 09:12:35,620 INFO django.server "GET /admin/ HTTP/1.1" 200 6427
2024-11-19 09:12:37,196 INFO django.server "GET /admin/authtoken/tokenproxy/ HTTP/1.1" 200 7625
2024-11-19 09:12:37,230 INFO django.server "GET /static/admin/css/changelists.css HTTP/1.1" 200 6811
2024-11-19 09:12:37,232 INFO django.server "GET /static/admin/js/admin/RelatedObjectLookups.js HTTP/1.1" 200 9042
2024-11-19 09:12:37,233 INFO django.server "GET /static/admin/js/jquery.init.js HTTP/1.1" 200 347
2024-11-19 09:12:37,234 INFO django.server "GET /static/admin/js/actions.js HTTP/1.1" 200 8067
2024-11-19 09:12:37,235 INFO django.server "GET /static/admin/js/core.js HTTP/1.1" 200 6208
2024-11-19 09:12:37,236 INFO django.server "GET /static/admin/js/urlify.js HTTP/1.1" 200 7887
2024-11-19 09:12:37,238 INFO django.server "GET /static/admin/js/prepopulate.js HTTP/1.1" 200 1531
2024-11-19 09:12:37,239 INFO django.server "GET /static/admin/js/filters.js HTTP/1.1" 200 978
2024-11-19 09:12:37,242 INFO django.server "GET /static/admin/js/vendor/jquery/jquery.js HTTP/1.1" 200 285314
2024-11-19 09:12:37,243 INFO django.server "GET /static/admin/js/vendor/xregexp/xregexp.js HTTP/1.1" 200 325171
2024-11-19 09:12:37,283 INFO django.server "GET /static/admin/img/tooltag-add.svg HTTP/1.1" 200 331
2024-11-19 09:12:38,514 INFO django.server "GET /admin/authtoken/ HTTP/1.1" 200 5089
2024-11-19 09:12:39,933 INFO django.server "GET /admin/authtoken/tokenproxy/ HTTP/1.1" 200 7625
2024-11-19 09:12:40,596 INFO django.server "GET /admin/ HTTP/1.1" 200 6427
2024-11-19 09:12:41,664 INFO django.server "GET /admin/storage/ HTTP/1.1" 200 5037
2024-11-19 09:12:42,720 INFO django.server "GET /admin/ HTTP/1.1" 200 6427
2024-11-19 09:15:27,353 INFO django.server "GET /admin/accounts/user/add/ HTTP/1.1" 200 14744
2024-11-19 09:15:27,401 INFO django.server "GET /static/admin/css/forms.css HTTP/1.1" 200 9048
2024-11-19 09:15:27,405 INFO django.server "GET /static/admin/js/inlines.js HTTP/1.1" 200 15526
2024-11-19 09:15:27,406 INFO django.server "GET /static/admin/js/change_form.js HTTP/1.1" 200 606
2024-11-19 09:15:27,406 INFO django.server "GET /static/admin/js/prepopulate_init.js HTTP/1.1" 200 586
2024-11-19 09:15:27,412 INFO django.server "GET /admin/jsi18n/ HTTP/1.1" 200 3342
2024-11-19 09:15:27,423 INFO django.server "GET /static/admin/css/widgets.css HTTP/1.1" 200 11800
2024-11-19 09:15:27,458 WARNING django.request Not Found: /favicon.ico
2024-11-19 09:15:27,459 WARNING django.server "GET /favicon.ico HTTP/1.1" 404 2979
2024-11-19 09:16:07,980 INFO django.server "POST /admin/accounts/user/add/ HTTP/1.1" 302 0
2024-11-19 09:16:08,045 ERROR django.request Internal Server Error: /admin/accounts/user/2/change/
Traceback (most recent call last):
  File "/usr/local/lib/python3.10/site-packages/django/db/backends/utils.py", line 105, in _execute
    return self.cursor.execute(sql, params)
psycopg2.errors.UndefinedTable: relation "storage_file" does not exist
LINE 1: ...pload_datetime", "storage_file"."by_user_id" FROM "storage_f...
                                                             ^


The above exception was the direct cause of the following exception:

Traceback (most recent call last):
  File "/usr/local/lib/python3.10/site-packages/django/core/handlers/exception.py", line 55, in inner
    response = get_response(request)
  File "/usr/local/lib/python3.10/site-packages/django/core/handlers/base.py", line 197, in _get_response
    response = wrapped_callback(request, *callback_args, **callback_kwargs)
  File "/usr/local/lib/python3.10/site-packages/django/contrib/admin/options.py", line 714, in wrapper
    return self.admin_site.admin_view(view)(*args, **kwargs)
  File "/usr/local/lib/python3.10/site-packages/django/utils/decorators.py", line 188, in _view_wrapper
    result = _process_exception(request, e)
  File "/usr/local/lib/python3.10/site-packages/django/utils/decorators.py", line 186, in _view_wrapper
    response = view_func(request, *args, **kwargs)
  File "/usr/local/lib/python3.10/site-packages/django/views/decorators/cache.py", line 80, in _view_wrapper
    response = view_func(request, *args, **kwargs)
  File "/usr/local/lib/python3.10/site-packages/django/contrib/admin/sites.py", line 240, in inner
    return view(request, *args, **kwargs)
  File "/usr/local/lib/python3.10/site-packages/django/contrib/admin/options.py", line 1944, in change_view
    return self.changeform_view(request, object_id, form_url, extra_context)
  File "/usr/local/lib/python3.10/site-packages/django/utils/decorators.py", line 48, in _wrapper
    return bound_method(*args, **kwargs)
  File "/usr/local/lib/python3.10/site-packages/django/utils/decorators.py", line 188, in _view_wrapper
    result = _process_exception(request, e)
  File "/usr/local/lib/python3.10/site-packages/django/utils/decorators.py", line 186, in _view_wrapper
    response = view_func(request, *args, **kwargs)
  File "/usr/local/lib/python3.10/site-packages/django/contrib/admin/options.py", line 1802, in changeform_view
    return self._changeform_view(request, object_id, form_url, extra_context)
  File "/usr/local/lib/python3.10/site-packages/django/contrib/admin/options.py", line 1899, in _changeform_view
    media += inline_formset.media
  File "/usr/local/lib/python3.10/site-packages/django/contrib/admin/helpers.py", line 454, in media
    media = self.opts.media + self.formset.media
  File "/usr/local/lib/python3.10/site-packages/django/forms/formsets.py", line 521, in media
    if self.forms:
  File "/usr/local/lib/python3.10/site-packages/django/utils/functional.py", line 47, in __get__
    res = instance.__dict__[self.name] = self.func(instance)
  File "/usr/local/lib/python3.10/site-packages/django/forms/formsets.py", line 207, in forms
    for i in range(self.total_form_count())
  File "/usr/local/lib/python3.10/site-packages/django/forms/formsets.py", line 182, in total_form_count
    initial_forms = self.initial_form_count()
  File "/usr/local/lib/python3.10/site-packages/django/forms/models.py", line 1117, in initial_form_count
    return super().initial_form_count()
  File "/usr/local/lib/python3.10/site-packages/django/forms/models.py", line 694, in initial_form_count
    return len(self.get_queryset())
  File "/usr/local/lib/python3.10/site-packages/django/db/models/query.py", line 380, in __len__
    self._fetch_all()
  File "/usr/local/lib/python3.10/site-packages/django/db/models/query.py", line 1926, in _fetch_all
    self._result_cache = list(self._iterable_class(self))
  File "/usr/local/lib/python3.10/site-packages/django/db/models/query.py", line 91, in __iter__
    results = compiler.execute_sql(
  File "/usr/local/lib/python3.10/site-packages/django/db/models/sql/compiler.py", line 1562, in execute_sql
    cursor.execute(sql, params)
  File "/usr/local/lib/python3.10/site-packages/django/db/backends/utils.py", line 122, in execute
    return super().execute(sql, params)
  File "/usr/local/lib/python3.10/site-packages/django/db/backends/utils.py", line 79, in execute
    return self._execute_with_wrappers(
  File "/usr/local/lib/python3.10/site-packages/django/db/backends/utils.py", line 92, in _execute_with_wrappers
    return executor(sql, params, many, context)
  File "/usr/local/lib/python3.10/site-packages/django/db/backends/utils.py", line 100, in _execute
    with self.db.wrap_database_errors:
  File "/usr/local/lib/python3.10/site-packages/django/db/utils.py", line 91, in __exit__
    raise dj_exc_value.with_traceback(traceback) from exc_value
  File "/usr/local/lib/python3.10/site-packages/django/db/backends/utils.py", line 105, in _execute
    return self.cursor.execute(sql, params)
django.db.utils.ProgrammingError: relation "storage_file" does not exist
LINE 1: ...pload_datetime", "storage_file"."by_user_id" FROM "storage_f...
                                                             ^

2024-11-19 09:16:08,047 ERROR django.server "GET /admin/accounts/user/2/change/ HTTP/1.1" 500 197312
2024-11-19 09:16:14,255 INFO django.server "GET /admin/accounts/user/add/ HTTP/1.1" 200 14971
2024-11-19 09:16:14,300 INFO django.server "GET /static/admin/js/prepopulate_init.js HTTP/1.1" 200 586
2024-11-19 09:16:14,344 INFO django.server "GET /static/admin/img/icon-yes.svg HTTP/1.1" 200 436
2024-11-19 09:16:14,363 WARNING django.request Not Found: /favicon.ico
2024-11-19 09:16:14,364 WARNING django.server "GET /favicon.ico HTTP/1.1" 404 2979
2024-11-19 09:16:17,138 ERROR django.request Internal Server Error: /admin/accounts/user/
Traceback (most recent call last):
  File "/usr/local/lib/python3.10/site-packages/django/db/models/options.py", line 681, in get_field
    return self.fields_map[field_name]
KeyError: 'file_count'

During handling of the above exception, another exception occurred:

Traceback (most recent call last):
  File "/usr/local/lib/python3.10/site-packages/django/contrib/admin/utils.py", line 289, in lookup_field
    f = _get_non_gfk_field(opts, name)
  File "/usr/local/lib/python3.10/site-packages/django/contrib/admin/utils.py", line 322, in _get_non_gfk_field
    field = opts.get_field(name)
  File "/usr/local/lib/python3.10/site-packages/django/db/models/options.py", line 683, in get_field
    raise FieldDoesNotExist(
django.core.exceptions.FieldDoesNotExist: User has no field named 'file_count'

During handling of the above exception, another exception occurred:

Traceback (most recent call last):
  File "/usr/local/lib/python3.10/site-packages/django/db/backends/utils.py", line 105, in _execute
    return self.cursor.execute(sql, params)
psycopg2.errors.UndefinedTable: relation "storage_file" does not exist
LINE 1: SELECT COUNT(*) AS "__count" FROM "storage_file" WHERE "stor...
                                          ^


The above exception was the direct cause of the following exception:

Traceback (most recent call last):
  File "/usr/local/lib/python3.10/site-packages/django/core/handlers/exception.py", line 55, in inner
    response = get_response(request)
  File "/usr/local/lib/python3.10/site-packages/django/core/handlers/base.py", line 220, in _get_response
    response = response.render()
  File "/usr/local/lib/python3.10/site-packages/django/template/response.py", line 114, in render
    self.content = self.rendered_content
  File "/usr/local/lib/python3.10/site-packages/django/template/response.py", line 92, in rendered_content
    return template.render(context, self._request)
  File "/usr/local/lib/python3.10/site-packages/django/template/backends/django.py", line 61, in render
    return self.template.render(context)
  File "/usr/local/lib/python3.10/site-packages/django/template/base.py", line 171, in render
    return self._render(context)
  File "/usr/local/lib/python3.10/site-packages/django/template/base.py", line 163, in _render
    return self.nodelist.render(context)
  File "/usr/local/lib/python3.10/site-packages/django/template/base.py", line 1000, in render
    return SafeString("".join([node.render_annotated(context) for node in self]))
  File "/usr/local/lib/python3.10/site-packages/django/template/base.py", line 1000, in <listcomp>
    return SafeString("".join([node.render_annotated(context) for node in self]))
  File "/usr/local/lib/python3.10/site-packages/django/template/base.py", line 961, in render_annotated
    return self.render(context)
  File "/usr/local/lib/python3.10/site-packages/django/template/loader_tags.py", line 159, in render
    return compiled_parent._render(context)
  File "/usr/local/lib/python3.10/site-packages/django/template/base.py", line 163, in _render
    return self.nodelist.render(context)
  File "/usr/local/lib/python3.10/site-packages/django/template/base.py", line 1000, in render
    return SafeString("".join([node.render_annotated(context) for node in self]))
  File "/usr/local/lib/python3.10/site-packages/django/template/base.py", line 1000, in <listcomp>
    return SafeString("".join([node.render_annotated(context) for node in self]))
  File "/usr/local/lib/python3.10/site-packages/django/template/base.py", line 961, in render_annotated
    return self.render(context)
  File "/usr/local/lib/python3.10/site-packages/django/template/loader_tags.py", line 159, in render
    return compiled_parent._render(context)
  File "/usr/local/lib/python3.10/site-packages/django/template/base.py", line 163, in _render
    return self.nodelist.render(context)
  File "/usr/local/lib/python3.10/site-packages/django/template/base.py", line 1000, in render
    return SafeString("".join([node.render_annotated(context) for node in self]))
  File "/usr/local/lib/python3.10/site-packages/django/template/base.py", line 1000, in <listcomp>
    return SafeString("".join([node.render_annotated(context) for node in self]))
  File "/usr/local/lib/python3.10/site-packages/django/template/base.py", line 961, in render_annotated
    return self.render(context)
  File "/usr/local/lib/python3.10/site-packages/django/template/loader_tags.py", line 65, in render
    result = block.nodelist.render(context)
  File "/usr/local/lib/python3.10/site-packages/django/template/base.py", line 1000, in render
    return SafeString("".join([node.render_annotated(context) for node in self]))
  File "/usr/local/lib/python3.10/site-packages/django/template/base.py", line 1000, in <listcomp>
    return SafeString("".join([node.render_annotated(context) for node in self]))
  File "/usr/local/lib/python3.10/site-packages/django/template/base.py", line 961, in render_annotated
    return self.render(context)
  File "/usr/local/lib/python3.10/site-packages/django/template/loader_tags.py", line 65, in render
    result = block.nodelist.render(context)
  File "/usr/local/lib/python3.10/site-packages/django/template/base.py", line 1000, in render
    return SafeString("".join([node.render_annotated(context) for node in self]))
  File "/usr/local/lib/python3.10/site-packages/django/template/base.py", line 1000, in <listcomp>
    return SafeString("".join([node.render_annotated(context) for node in self]))
  File "/usr/local/lib/python3.10/site-packages/django/template/base.py", line 961, in render_annotated
    return self.render(context)
  File "/usr/local/lib/python3.10/site-packages/django/contrib/admin/templatetags/base.py", line 45, in render
    return super().render(context)
  File "/usr/local/lib/python3.10/site-packages/django/template/library.py", line 258, in render
    _dict = self.func(*resolved_args, **resolved_kwargs)
  File "/usr/local/lib/python3.10/site-packages/django/contrib/admin/templatetags/admin_list.py", line 343, in result_list
    "results": list(results(cl)),
  File "/usr/local/lib/python3.10/site-packages/django/contrib/admin/templatetags/admin_list.py", line 319, in results
    yield ResultList(None, items_for_result(cl, res, None))
  File "/usr/local/lib/python3.10/site-packages/django/contrib/admin/templatetags/admin_list.py", line 310, in __init__
    super().__init__(*items)
  File "/usr/local/lib/python3.10/site-packages/django/contrib/admin/templatetags/admin_list.py", line 217, in items_for_result
    f, attr, value = lookup_field(field_name, result, cl.model_admin)
  File "/usr/local/lib/python3.10/site-packages/django/contrib/admin/utils.py", line 298, in lookup_field
    value = attr(obj)
  File "/app/accounts/admin.py", line 35, in file_count
    return obj.file_set.count()
  File "/usr/local/lib/python3.10/site-packages/django/db/models/manager.py", line 87, in manager_method
    return getattr(self.get_queryset(), name)(*args, **kwargs)
  File "/usr/local/lib/python3.10/site-packages/django/db/models/query.py", line 618, in count
    return self.query.get_count(using=self.db)
  File "/usr/local/lib/python3.10/site-packages/django/db/models/sql/query.py", line 616, in get_count
    return obj.get_aggregation(using, {"__count": Count("*")})["__count"]
  File "/usr/local/lib/python3.10/site-packages/django/db/models/sql/query.py", line 602, in get_aggregation
    result = compiler.execute_sql(SINGLE)
  File "/usr/local/lib/python3.10/site-packages/django/db/models/sql/compiler.py", line 1562, in execute_sql
    cursor.execute(sql, params)
  File "/usr/local/lib/python3.10/site-packages/django/db/backends/utils.py", line 122, in execute
    return super().execute(sql, params)
  File "/usr/local/lib/python3.10/site-packages/django/db/backends/utils.py", line 79, in execute
    return self._execute_with_wrappers(
  File "/usr/local/lib/python3.10/site-packages/django/db/backends/utils.py", line 92, in _execute_with_wrappers
    return executor(sql, params, many, context)
  File "/usr/local/lib/python3.10/site-packages/django/db/backends/utils.py", line 100, in _execute
    with self.db.wrap_database_errors:
  File "/usr/local/lib/python3.10/site-packages/django/db/utils.py", line 91, in __exit__
    raise dj_exc_value.with_traceback(traceback) from exc_value
  File "/usr/local/lib/python3.10/site-packages/django/db/backends/utils.py", line 105, in _execute
    return self.cursor.execute(sql, params)
django.db.utils.ProgrammingError: relation "storage_file" does not exist
LINE 1: SELECT COUNT(*) AS "__count" FROM "storage_file" WHERE "stor...
                                          ^

2024-11-19 09:16:17,141 ERROR django.server "GET /admin/accounts/user/ HTTP/1.1" 500 414427
2024-11-19 09:16:17,209 WARNING django.request Not Found: /favicon.ico
2024-11-19 09:16:17,210 WARNING django.server "GET /favicon.ico HTTP/1.1" 404 2979
2024-11-19 09:16:19,524 INFO django.server "GET /admin/accounts/user/add/ HTTP/1.1" 200 14744
2024-11-19 09:16:20,324 INFO django.server "GET /admin/ HTTP/1.1" 200 6804
2024-11-19 09:16:21,135 INFO django.server "GET /admin/login/?next=/admin/ HTTP/1.1" 302 0
2024-11-19 09:16:21,162 INFO django.server "GET /admin/ HTTP/1.1" 200 6804
2024-11-19 09:16:22,858 INFO django.server "GET /admin/accounts/ HTTP/1.1" 200 5048
2024-11-19 09:16:23,862 ERROR django.request Internal Server Error: /admin/accounts/user/
Traceback (most recent call last):
  File "/usr/local/lib/python3.10/site-packages/django/db/models/options.py", line 681, in get_field
    return self.fields_map[field_name]
KeyError: 'file_count'

During handling of the above exception, another exception occurred:

Traceback (most recent call last):
  File "/usr/local/lib/python3.10/site-packages/django/contrib/admin/utils.py", line 289, in lookup_field
    f = _get_non_gfk_field(opts, name)
  File "/usr/local/lib/python3.10/site-packages/django/contrib/admin/utils.py", line 322, in _get_non_gfk_field
    field = opts.get_field(name)
  File "/usr/local/lib/python3.10/site-packages/django/db/models/options.py", line 683, in get_field
    raise FieldDoesNotExist(
django.core.exceptions.FieldDoesNotExist: User has no field named 'file_count'

During handling of the above exception, another exception occurred:

Traceback (most recent call last):
  File "/usr/local/lib/python3.10/site-packages/django/db/backends/utils.py", line 105, in _execute
    return self.cursor.execute(sql, params)
psycopg2.errors.UndefinedTable: relation "storage_file" does not exist
LINE 1: SELECT COUNT(*) AS "__count" FROM "storage_file" WHERE "stor...
                                          ^


The above exception was the direct cause of the following exception:

Traceback (most recent call last):
  File "/usr/local/lib/python3.10/site-packages/django/core/handlers/exception.py", line 55, in inner
    response = get_response(request)
  File "/usr/local/lib/python3.10/site-packages/django/core/handlers/base.py", line 220, in _get_response
    response = response.render()
  File "/usr/local/lib/python3.10/site-packages/django/template/response.py", line 114, in render
    self.content = self.rendered_content
  File "/usr/local/lib/python3.10/site-packages/django/template/response.py", line 92, in rendered_content
    return template.render(context, self._request)
  File "/usr/local/lib/python3.10/site-packages/django/template/backends/django.py", line 61, in render
    return self.template.render(context)
  File "/usr/local/lib/python3.10/site-packages/django/template/base.py", line 171, in render
    return self._render(context)
  File "/usr/local/lib/python3.10/site-packages/django/template/base.py", line 163, in _render
    return self.nodelist.render(context)
  File "/usr/local/lib/python3.10/site-packages/django/template/base.py", line 1000, in render
    return SafeString("".join([node.render_annotated(context) for node in self]))
  File "/usr/local/lib/python3.10/site-packages/django/template/base.py", line 1000, in <listcomp>
    return SafeString("".join([node.render_annotated(context) for node in self]))
  File "/usr/local/lib/python3.10/site-packages/django/template/base.py", line 961, in render_annotated
    return self.render(context)
  File "/usr/local/lib/python3.10/site-packages/django/template/loader_tags.py", line 159, in render
    return compiled_parent._render(context)
  File "/usr/local/lib/python3.10/site-packages/django/template/base.py", line 163, in _render
    return self.nodelist.render(context)
  File "/usr/local/lib/python3.10/site-packages/django/template/base.py", line 1000, in render
    return SafeString("".join([node.render_annotated(context) for node in self]))
  File "/usr/local/lib/python3.10/site-packages/django/template/base.py", line 1000, in <listcomp>
    return SafeString("".join([node.render_annotated(context) for node in self]))
  File "/usr/local/lib/python3.10/site-packages/django/template/base.py", line 961, in render_annotated
    return self.render(context)
  File "/usr/local/lib/python3.10/site-packages/django/template/loader_tags.py", line 159, in render
    return compiled_parent._render(context)
  File "/usr/local/lib/python3.10/site-packages/django/template/base.py", line 163, in _render
    return self.nodelist.render(context)
  File "/usr/local/lib/python3.10/site-packages/django/template/base.py", line 1000, in render
    return SafeString("".join([node.render_annotated(context) for node in self]))
  File "/usr/local/lib/python3.10/site-packages/django/template/base.py", line 1000, in <listcomp>
    return SafeString("".join([node.render_annotated(context) for node in self]))
  File "/usr/local/lib/python3.10/site-packages/django/template/base.py", line 961, in render_annotated
    return self.render(context)
  File "/usr/local/lib/python3.10/site-packages/django/template/loader_tags.py", line 65, in render
    result = block.nodelist.render(context)
  File "/usr/local/lib/python3.10/site-packages/django/template/base.py", line 1000, in render
    return SafeString("".join([node.render_annotated(context) for node in self]))
  File "/usr/local/lib/python3.10/site-packages/django/template/base.py", line 1000, in <listcomp>
    return SafeString("".join([node.render_annotated(context) for node in self]))
  File "/usr/local/lib/python3.10/site-packages/django/template/base.py", line 961, in render_annotated
    return self.render(context)
  File "/usr/local/lib/python3.10/site-packages/django/template/loader_tags.py", line 65, in render
    result = block.nodelist.render(context)
  File "/usr/local/lib/python3.10/site-packages/django/template/base.py", line 1000, in render
    return SafeString("".join([node.render_annotated(context) for node in self]))
  File "/usr/local/lib/python3.10/site-packages/django/template/base.py", line 1000, in <listcomp>
    return SafeString("".join([node.render_annotated(context) for node in self]))
  File "/usr/local/lib/python3.10/site-packages/django/template/base.py", line 961, in render_annotated
    return self.render(context)
  File "/usr/local/lib/python3.10/site-packages/django/contrib/admin/templatetags/base.py", line 45, in render
    return super().render(context)
  File "/usr/local/lib/python3.10/site-packages/django/template/library.py", line 258, in render
    _dict = self.func(*resolved_args, **resolved_kwargs)
  File "/usr/local/lib/python3.10/site-packages/django/contrib/admin/templatetags/admin_list.py", line 343, in result_list
    "results": list(results(cl)),
  File "/usr/local/lib/python3.10/site-packages/django/contrib/admin/templatetags/admin_list.py", line 319, in results
    yield ResultList(None, items_for_result(cl, res, None))
  File "/usr/local/lib/python3.10/site-packages/django/contrib/admin/templatetags/admin_list.py", line 310, in __init__
    super().__init__(*items)
  File "/usr/local/lib/python3.10/site-packages/django/contrib/admin/templatetags/admin_list.py", line 217, in items_for_result
    f, attr, value = lookup_field(field_name, result, cl.model_admin)
  File "/usr/local/lib/python3.10/site-packages/django/contrib/admin/utils.py", line 298, in lookup_field
    value = attr(obj)
  File "/app/accounts/admin.py", line 35, in file_count
    return obj.file_set.count()
  File "/usr/local/lib/python3.10/site-packages/django/db/models/manager.py", line 87, in manager_method
    return getattr(self.get_queryset(), name)(*args, **kwargs)
  File "/usr/local/lib/python3.10/site-packages/django/db/models/query.py", line 618, in count
    return self.query.get_count(using=self.db)
  File "/usr/local/lib/python3.10/site-packages/django/db/models/sql/query.py", line 616, in get_count
    return obj.get_aggregation(using, {"__count": Count("*")})["__count"]
  File "/usr/local/lib/python3.10/site-packages/django/db/models/sql/query.py", line 602, in get_aggregation
    result = compiler.execute_sql(SINGLE)
  File "/usr/local/lib/python3.10/site-packages/django/db/models/sql/compiler.py", line 1562, in execute_sql
    cursor.execute(sql, params)
  File "/usr/local/lib/python3.10/site-packages/django/db/backends/utils.py", line 122, in execute
    return super().execute(sql, params)
  File "/usr/local/lib/python3.10/site-packages/django/db/backends/utils.py", line 79, in execute
    return self._execute_with_wrappers(
  File "/usr/local/lib/python3.10/site-packages/django/db/backends/utils.py", line 92, in _execute_with_wrappers
    return executor(sql, params, many, context)
  File "/usr/local/lib/python3.10/site-packages/django/db/backends/utils.py", line 100, in _execute
    with self.db.wrap_database_errors:
  File "/usr/local/lib/python3.10/site-packages/django/db/utils.py", line 91, in __exit__
    raise dj_exc_value.with_traceback(traceback) from exc_value
  File "/usr/local/lib/python3.10/site-packages/django/db/backends/utils.py", line 105, in _execute
    return self.cursor.execute(sql, params)
django.db.utils.ProgrammingError: relation "storage_file" does not exist
LINE 1: SELECT COUNT(*) AS "__count" FROM "storage_file" WHERE "stor...
                                          ^

2024-11-19 09:16:23,863 ERROR django.server "GET /admin/accounts/user/ HTTP/1.1" 500 414418
2024-11-19 09:16:29,014 INFO django.server "GET /admin/accounts/ HTTP/1.1" 200 5048
2024-11-19 09:16:29,710 INFO django.server "GET /admin/ HTTP/1.1" 200 6804
2024-11-19 09:16:31,731 ERROR django.request Internal Server Error: /admin/accounts/user/2/change/
Traceback (most recent call last):
  File "/usr/local/lib/python3.10/site-packages/django/db/backends/utils.py", line 105, in _execute
    return self.cursor.execute(sql, params)
psycopg2.errors.UndefinedTable: relation "storage_file" does not exist
LINE 1: ...pload_datetime", "storage_file"."by_user_id" FROM "storage_f...
                                                             ^


The above exception was the direct cause of the following exception:

Traceback (most recent call last):
  File "/usr/local/lib/python3.10/site-packages/django/core/handlers/exception.py", line 55, in inner
    response = get_response(request)
  File "/usr/local/lib/python3.10/site-packages/django/core/handlers/base.py", line 197, in _get_response
    response = wrapped_callback(request, *callback_args, **callback_kwargs)
  File "/usr/local/lib/python3.10/site-packages/django/contrib/admin/options.py", line 714, in wrapper
    return self.admin_site.admin_view(view)(*args, **kwargs)
  File "/usr/local/lib/python3.10/site-packages/django/utils/decorators.py", line 188, in _view_wrapper
    result = _process_exception(request, e)
  File "/usr/local/lib/python3.10/site-packages/django/utils/decorators.py", line 186, in _view_wrapper
    response = view_func(request, *args, **kwargs)
  File "/usr/local/lib/python3.10/site-packages/django/views/decorators/cache.py", line 80, in _view_wrapper
    response = view_func(request, *args, **kwargs)
  File "/usr/local/lib/python3.10/site-packages/django/contrib/admin/sites.py", line 240, in inner
    return view(request, *args, **kwargs)
  File "/usr/local/lib/python3.10/site-packages/django/contrib/admin/options.py", line 1944, in change_view
    return self.changeform_view(request, object_id, form_url, extra_context)
  File "/usr/local/lib/python3.10/site-packages/django/utils/decorators.py", line 48, in _wrapper
    return bound_method(*args, **kwargs)
  File "/usr/local/lib/python3.10/site-packages/django/utils/decorators.py", line 188, in _view_wrapper
    result = _process_exception(request, e)
  File "/usr/local/lib/python3.10/site-packages/django/utils/decorators.py", line 186, in _view_wrapper
    response = view_func(request, *args, **kwargs)
  File "/usr/local/lib/python3.10/site-packages/django/contrib/admin/options.py", line 1802, in changeform_view
    return self._changeform_view(request, object_id, form_url, extra_context)
  File "/usr/local/lib/python3.10/site-packages/django/contrib/admin/options.py", line 1899, in _changeform_view
    media += inline_formset.media
  File "/usr/local/lib/python3.10/site-packages/django/contrib/admin/helpers.py", line 454, in media
    media = self.opts.media + self.formset.media
  File "/usr/local/lib/python3.10/site-packages/django/forms/formsets.py", line 521, in media
    if self.forms:
  File "/usr/local/lib/python3.10/site-packages/django/utils/functional.py", line 47, in __get__
    res = instance.__dict__[self.name] = self.func(instance)
  File "/usr/local/lib/python3.10/site-packages/django/forms/formsets.py", line 207, in forms
    for i in range(self.total_form_count())
  File "/usr/local/lib/python3.10/site-packages/django/forms/formsets.py", line 182, in total_form_count
    initial_forms = self.initial_form_count()
  File "/usr/local/lib/python3.10/site-packages/django/forms/models.py", line 1117, in initial_form_count
    return super().initial_form_count()
  File "/usr/local/lib/python3.10/site-packages/django/forms/models.py", line 694, in initial_form_count
    return len(self.get_queryset())
  File "/usr/local/lib/python3.10/site-packages/django/db/models/query.py", line 380, in __len__
    self._fetch_all()
  File "/usr/local/lib/python3.10/site-packages/django/db/models/query.py", line 1926, in _fetch_all
    self._result_cache = list(self._iterable_class(self))
  File "/usr/local/lib/python3.10/site-packages/django/db/models/query.py", line 91, in __iter__
    results = compiler.execute_sql(
  File "/usr/local/lib/python3.10/site-packages/django/db/models/sql/compiler.py", line 1562, in execute_sql
    cursor.execute(sql, params)
  File "/usr/local/lib/python3.10/site-packages/django/db/backends/utils.py", line 122, in execute
    return super().execute(sql, params)
  File "/usr/local/lib/python3.10/site-packages/django/db/backends/utils.py", line 79, in execute
    return self._execute_with_wrappers(
  File "/usr/local/lib/python3.10/site-packages/django/db/backends/utils.py", line 92, in _execute_with_wrappers
    return executor(sql, params, many, context)
  File "/usr/local/lib/python3.10/site-packages/django/db/backends/utils.py", line 100, in _execute
    with self.db.wrap_database_errors:
  File "/usr/local/lib/python3.10/site-packages/django/db/utils.py", line 91, in __exit__
    raise dj_exc_value.with_traceback(traceback) from exc_value
  File "/usr/local/lib/python3.10/site-packages/django/db/backends/utils.py", line 105, in _execute
    return self.cursor.execute(sql, params)
django.db.utils.ProgrammingError: relation "storage_file" does not exist
LINE 1: ...pload_datetime", "storage_file"."by_user_id" FROM "storage_f...
                                                             ^

2024-11-19 09:16:31,732 ERROR django.server "GET /admin/accounts/user/2/change/ HTTP/1.1" 500 196927
2024-11-19 09:16:32,737 INFO django.server "GET /admin/ HTTP/1.1" 200 6804
2024-11-19 09:16:36,775 INFO django.server "GET /admin/storage/file/add/ HTTP/1.1" 200 13613
2024-11-19 09:16:36,833 INFO django.server "GET /static/admin/js/calendar.js HTTP/1.1" 200 9141
2024-11-19 09:16:36,833 INFO django.server "GET /static/admin/js/change_form.js HTTP/1.1" 200 606
2024-11-19 09:16:36,834 INFO django.server "GET /static/admin/js/prepopulate_init.js HTTP/1.1" 200 586
2024-11-19 09:16:36,834 INFO django.server "GET /static/admin/js/admin/DateTimeShortcuts.js HTTP/1.1" 200 19319
2024-11-19 09:16:36,841 INFO django.server "GET /admin/jsi18n/ HTTP/1.1" 200 3342
2024-11-19 09:16:36,842 INFO django.server "GET /static/admin/img/icon-viewlink.svg HTTP/1.1" 200 581
2024-11-19 09:16:36,893 WARNING django.request Not Found: /favicon.ico
2024-11-19 09:16:36,893 WARNING django.server "GET /favicon.ico HTTP/1.1" 404 2979
2024-11-19 09:16:36,906 INFO django.server "GET /static/admin/img/icon-clock.svg HTTP/1.1" 200 677
2024-11-19 09:16:36,906 INFO django.server "GET /static/admin/img/icon-calendar.svg HTTP/1.1" 200 1086
2024-11-19 09:16:53,492 ERROR django.request Internal Server Error: /admin/storage/file/add/
Traceback (most recent call last):
  File "/usr/local/lib/python3.10/site-packages/django/db/backends/utils.py", line 105, in _execute
    return self.cursor.execute(sql, params)
psycopg2.errors.UndefinedTable: relation "storage_file" does not exist
LINE 1: ...pload_datetime", "storage_file"."by_user_id" FROM "storage_f...
                                                             ^


The above exception was the direct cause of the following exception:

Traceback (most recent call last):
  File "/usr/local/lib/python3.10/site-packages/django/core/handlers/exception.py", line 55, in inner
    response = get_response(request)
  File "/usr/local/lib/python3.10/site-packages/django/core/handlers/base.py", line 197, in _get_response
    response = wrapped_callback(request, *callback_args, **callback_kwargs)
  File "/usr/local/lib/python3.10/site-packages/django/contrib/admin/options.py", line 714, in wrapper
    return self.admin_site.admin_view(view)(*args, **kwargs)
  File "/usr/local/lib/python3.10/site-packages/django/utils/decorators.py", line 188, in _view_wrapper
    result = _process_exception(request, e)
  File "/usr/local/lib/python3.10/site-packages/django/utils/decorators.py", line 186, in _view_wrapper
    response = view_func(request, *args, **kwargs)
  File "/usr/local/lib/python3.10/site-packages/django/views/decorators/cache.py", line 80, in _view_wrapper
    response = view_func(request, *args, **kwargs)
  File "/usr/local/lib/python3.10/site-packages/django/contrib/admin/sites.py", line 240, in inner
    return view(request, *args, **kwargs)
  File "/usr/local/lib/python3.10/site-packages/django/contrib/admin/options.py", line 1941, in add_view
    return self.changeform_view(request, None, form_url, extra_context)
  File "/usr/local/lib/python3.10/site-packages/django/utils/decorators.py", line 48, in _wrapper
    return bound_method(*args, **kwargs)
  File "/usr/local/lib/python3.10/site-packages/django/utils/decorators.py", line 188, in _view_wrapper
    result = _process_exception(request, e)
  File "/usr/local/lib/python3.10/site-packages/django/utils/decorators.py", line 186, in _view_wrapper
    response = view_func(request, *args, **kwargs)
  File "/usr/local/lib/python3.10/site-packages/django/contrib/admin/options.py", line 1802, in changeform_view
    return self._changeform_view(request, object_id, form_url, extra_context)
  File "/usr/local/lib/python3.10/site-packages/django/contrib/admin/options.py", line 1853, in _changeform_view
    self.save_model(request, new_object, form, not add)
  File "/usr/local/lib/python3.10/site-packages/django/contrib/admin/options.py", line 1257, in save_model
    obj.save()
  File "/app/storage/models.py", line 67, in save
    self.filename = check_unique_filename(userfolder, f'{self.filename}{file_ext}')
  File "/app/storage/models.py", line 22, in check_unique_filename
    if File.objects.filter(file=new_filepath):
  File "/usr/local/lib/python3.10/site-packages/django/db/models/query.py", line 412, in __bool__
    self._fetch_all()
  File "/usr/local/lib/python3.10/site-packages/django/db/models/query.py", line 1926, in _fetch_all
    self._result_cache = list(self._iterable_class(self))
  File "/usr/local/lib/python3.10/site-packages/django/db/models/query.py", line 91, in __iter__
    results = compiler.execute_sql(
  File "/usr/local/lib/python3.10/site-packages/django/db/models/sql/compiler.py", line 1562, in execute_sql
    cursor.execute(sql, params)
  File "/usr/local/lib/python3.10/site-packages/django/db/backends/utils.py", line 122, in execute
    return super().execute(sql, params)
  File "/usr/local/lib/python3.10/site-packages/django/db/backends/utils.py", line 79, in execute
    return self._execute_with_wrappers(
  File "/usr/local/lib/python3.10/site-packages/django/db/backends/utils.py", line 92, in _execute_with_wrappers
    return executor(sql, params, many, context)
  File "/usr/local/lib/python3.10/site-packages/django/db/backends/utils.py", line 100, in _execute
    with self.db.wrap_database_errors:
  File "/usr/local/lib/python3.10/site-packages/django/db/utils.py", line 91, in __exit__
    raise dj_exc_value.with_traceback(traceback) from exc_value
  File "/usr/local/lib/python3.10/site-packages/django/db/backends/utils.py", line 105, in _execute
    return self.cursor.execute(sql, params)
django.db.utils.ProgrammingError: relation "storage_file" does not exist
LINE 1: ...pload_datetime", "storage_file"."by_user_id" FROM "storage_f...
                                                             ^

2024-11-19 09:16:53,493 ERROR django.server "POST /admin/storage/file/add/ HTTP/1.1" 500 182574
2024-11-19 09:16:56,236 INFO django.server "GET /admin/storage/file/add/ HTTP/1.1" 200 13613
2024-11-19 09:16:56,312 WARNING django.request Not Found: /favicon.ico
2024-11-19 09:16:56,312 WARNING django.server "GET /favicon.ico HTTP/1.1" 404 2979
2024-11-19 09:16:56,728 INFO django.server "GET /admin/ HTTP/1.1" 200 6804
2024-11-19 09:16:57,105 WARNING django.request Method Not Allowed: /login/
2024-11-19 09:16:57,106 WARNING django.server "GET /login/ HTTP/1.1" 405 5582
2024-11-19 09:16:58,589 WARNING django.request Method Not Allowed: /register/
2024-11-19 09:16:58,590 WARNING django.server "GET /register/ HTTP/1.1" 405 5599
2024-11-19 09:16:59,044 INFO django.server "GET /admin/login/?next=/admin/ HTTP/1.1" 302 0
2024-11-19 09:16:59,067 INFO django.server "GET /admin/ HTTP/1.1" 200 6804
2024-11-19 09:21:11,749 INFO django.utils.autoreload Watching for file changes with StatReloader
2024-11-19 09:21:45,090 WARNING django.request Not Found: /
2024-11-19 09:21:45,090 WARNING django.server "GET / HTTP/1.1" 404 2928
2024-11-19 09:22:08,679 WARNING django.request Unauthorized: /api/
2024-11-19 09:22:08,679 WARNING django.server "GET /api/ HTTP/1.1" 401 5019
2024-11-19 09:27:14,217 WARNING django.request Not Found: /
2024-11-19 09:27:14,218 WARNING django.server "GET / HTTP/1.1" 404 2928
2024-11-19 09:27:15,027 WARNING django.request Not Found: /
2024-11-19 09:27:15,027 WARNING django.server "GET / HTTP/1.1" 404 2928
2024-11-19 09:29:15,332 INFO django.utils.autoreload Watching for file changes with StatReloader
2024-11-19 09:31:15,097 INFO django.server "GET /admin/ HTTP/1.1" 302 0
2024-11-19 09:31:15,120 INFO django.server "GET /admin/login/?next=/admin/ HTTP/1.1" 200 4158
2024-11-19 09:31:19,541 INFO django.server "POST /admin/login/?next=/admin/ HTTP/1.1" 302 0
2024-11-19 09:31:19,566 INFO django.server "GET /admin/ HTTP/1.1" 200 6427
2024-11-19 09:31:23,072 INFO django.server "GET /admin/accounts/user/add/ HTTP/1.1" 200 14744
2024-11-19 09:31:23,118 INFO django.server "GET /static/admin/js/prepopulate_init.js HTTP/1.1" 200 586
2024-11-19 09:31:23,127 INFO django.server "GET /admin/jsi18n/ HTTP/1.1" 200 3342
2024-11-19 09:31:23,130 INFO django.server "GET /static/admin/css/widgets.css HTTP/1.1" 200 11800
2024-11-19 09:31:23,178 WARNING django.request Not Found: /favicon.ico
2024-11-19 09:31:23,179 WARNING django.server "GET /favicon.ico HTTP/1.1" 404 2979
2024-11-19 09:31:48,189 INFO django.server "POST /admin/accounts/user/add/ HTTP/1.1" 302 0
2024-11-19 09:31:48,249 ERROR django.request Internal Server Error: /admin/accounts/user/2/change/
Traceback (most recent call last):
  File "/usr/local/lib/python3.10/site-packages/django/db/backends/utils.py", line 105, in _execute
    return self.cursor.execute(sql, params)
psycopg2.errors.UndefinedTable: relation "storage_file" does not exist
LINE 1: ...pload_datetime", "storage_file"."by_user_id" FROM "storage_f...
                                                             ^


The above exception was the direct cause of the following exception:

Traceback (most recent call last):
  File "/usr/local/lib/python3.10/site-packages/django/core/handlers/exception.py", line 55, in inner
    response = get_response(request)
  File "/usr/local/lib/python3.10/site-packages/django/core/handlers/base.py", line 197, in _get_response
    response = wrapped_callback(request, *callback_args, **callback_kwargs)
  File "/usr/local/lib/python3.10/site-packages/django/contrib/admin/options.py", line 714, in wrapper
    return self.admin_site.admin_view(view)(*args, **kwargs)
  File "/usr/local/lib/python3.10/site-packages/django/utils/decorators.py", line 188, in _view_wrapper
    result = _process_exception(request, e)
  File "/usr/local/lib/python3.10/site-packages/django/utils/decorators.py", line 186, in _view_wrapper
    response = view_func(request, *args, **kwargs)
  File "/usr/local/lib/python3.10/site-packages/django/views/decorators/cache.py", line 80, in _view_wrapper
    response = view_func(request, *args, **kwargs)
  File "/usr/local/lib/python3.10/site-packages/django/contrib/admin/sites.py", line 240, in inner
    return view(request, *args, **kwargs)
  File "/usr/local/lib/python3.10/site-packages/django/contrib/admin/options.py", line 1944, in change_view
    return self.changeform_view(request, object_id, form_url, extra_context)
  File "/usr/local/lib/python3.10/site-packages/django/utils/decorators.py", line 48, in _wrapper
    return bound_method(*args, **kwargs)
  File "/usr/local/lib/python3.10/site-packages/django/utils/decorators.py", line 188, in _view_wrapper
    result = _process_exception(request, e)
  File "/usr/local/lib/python3.10/site-packages/django/utils/decorators.py", line 186, in _view_wrapper
    response = view_func(request, *args, **kwargs)
  File "/usr/local/lib/python3.10/site-packages/django/contrib/admin/options.py", line 1802, in changeform_view
    return self._changeform_view(request, object_id, form_url, extra_context)
  File "/usr/local/lib/python3.10/site-packages/django/contrib/admin/options.py", line 1899, in _changeform_view
    media += inline_formset.media
  File "/usr/local/lib/python3.10/site-packages/django/contrib/admin/helpers.py", line 454, in media
    media = self.opts.media + self.formset.media
  File "/usr/local/lib/python3.10/site-packages/django/forms/formsets.py", line 521, in media
    if self.forms:
  File "/usr/local/lib/python3.10/site-packages/django/utils/functional.py", line 47, in __get__
    res = instance.__dict__[self.name] = self.func(instance)
  File "/usr/local/lib/python3.10/site-packages/django/forms/formsets.py", line 207, in forms
    for i in range(self.total_form_count())
  File "/usr/local/lib/python3.10/site-packages/django/forms/formsets.py", line 182, in total_form_count
    initial_forms = self.initial_form_count()
  File "/usr/local/lib/python3.10/site-packages/django/forms/models.py", line 1117, in initial_form_count
    return super().initial_form_count()
  File "/usr/local/lib/python3.10/site-packages/django/forms/models.py", line 694, in initial_form_count
    return len(self.get_queryset())
  File "/usr/local/lib/python3.10/site-packages/django/db/models/query.py", line 380, in __len__
    self._fetch_all()
  File "/usr/local/lib/python3.10/site-packages/django/db/models/query.py", line 1926, in _fetch_all
    self._result_cache = list(self._iterable_class(self))
  File "/usr/local/lib/python3.10/site-packages/django/db/models/query.py", line 91, in __iter__
    results = compiler.execute_sql(
  File "/usr/local/lib/python3.10/site-packages/django/db/models/sql/compiler.py", line 1562, in execute_sql
    cursor.execute(sql, params)
  File "/usr/local/lib/python3.10/site-packages/django/db/backends/utils.py", line 122, in execute
    return super().execute(sql, params)
  File "/usr/local/lib/python3.10/site-packages/django/db/backends/utils.py", line 79, in execute
    return self._execute_with_wrappers(
  File "/usr/local/lib/python3.10/site-packages/django/db/backends/utils.py", line 92, in _execute_with_wrappers
    return executor(sql, params, many, context)
  File "/usr/local/lib/python3.10/site-packages/django/db/backends/utils.py", line 100, in _execute
    with self.db.wrap_database_errors:
  File "/usr/local/lib/python3.10/site-packages/django/db/utils.py", line 91, in __exit__
    raise dj_exc_value.with_traceback(traceback) from exc_value
  File "/usr/local/lib/python3.10/site-packages/django/db/backends/utils.py", line 105, in _execute
    return self.cursor.execute(sql, params)
django.db.utils.ProgrammingError: relation "storage_file" does not exist
LINE 1: ...pload_datetime", "storage_file"."by_user_id" FROM "storage_f...
                                                             ^

2024-11-19 09:31:48,252 ERROR django.server "GET /admin/accounts/user/2/change/ HTTP/1.1" 500 197312
2024-11-19 09:31:57,851 INFO django.server "GET /admin/accounts/user/add/ HTTP/1.1" 200 14971
2024-11-19 09:31:59,976 ERROR django.request Internal Server Error: /admin/accounts/user/2/change/
Traceback (most recent call last):
  File "/usr/local/lib/python3.10/site-packages/django/db/backends/utils.py", line 105, in _execute
    return self.cursor.execute(sql, params)
psycopg2.errors.UndefinedTable: relation "storage_file" does not exist
LINE 1: ...pload_datetime", "storage_file"."by_user_id" FROM "storage_f...
                                                             ^


The above exception was the direct cause of the following exception:

Traceback (most recent call last):
  File "/usr/local/lib/python3.10/site-packages/django/core/handlers/exception.py", line 55, in inner
    response = get_response(request)
  File "/usr/local/lib/python3.10/site-packages/django/core/handlers/base.py", line 197, in _get_response
    response = wrapped_callback(request, *callback_args, **callback_kwargs)
  File "/usr/local/lib/python3.10/site-packages/django/contrib/admin/options.py", line 714, in wrapper
    return self.admin_site.admin_view(view)(*args, **kwargs)
  File "/usr/local/lib/python3.10/site-packages/django/utils/decorators.py", line 188, in _view_wrapper
    result = _process_exception(request, e)
  File "/usr/local/lib/python3.10/site-packages/django/utils/decorators.py", line 186, in _view_wrapper
    response = view_func(request, *args, **kwargs)
  File "/usr/local/lib/python3.10/site-packages/django/views/decorators/cache.py", line 80, in _view_wrapper
    response = view_func(request, *args, **kwargs)
  File "/usr/local/lib/python3.10/site-packages/django/contrib/admin/sites.py", line 240, in inner
    return view(request, *args, **kwargs)
  File "/usr/local/lib/python3.10/site-packages/django/contrib/admin/options.py", line 1944, in change_view
    return self.changeform_view(request, object_id, form_url, extra_context)
  File "/usr/local/lib/python3.10/site-packages/django/utils/decorators.py", line 48, in _wrapper
    return bound_method(*args, **kwargs)
  File "/usr/local/lib/python3.10/site-packages/django/utils/decorators.py", line 188, in _view_wrapper
    result = _process_exception(request, e)
  File "/usr/local/lib/python3.10/site-packages/django/utils/decorators.py", line 186, in _view_wrapper
    response = view_func(request, *args, **kwargs)
  File "/usr/local/lib/python3.10/site-packages/django/contrib/admin/options.py", line 1802, in changeform_view
    return self._changeform_view(request, object_id, form_url, extra_context)
  File "/usr/local/lib/python3.10/site-packages/django/contrib/admin/options.py", line 1899, in _changeform_view
    media += inline_formset.media
  File "/usr/local/lib/python3.10/site-packages/django/contrib/admin/helpers.py", line 454, in media
    media = self.opts.media + self.formset.media
  File "/usr/local/lib/python3.10/site-packages/django/forms/formsets.py", line 521, in media
    if self.forms:
  File "/usr/local/lib/python3.10/site-packages/django/utils/functional.py", line 47, in __get__
    res = instance.__dict__[self.name] = self.func(instance)
  File "/usr/local/lib/python3.10/site-packages/django/forms/formsets.py", line 207, in forms
    for i in range(self.total_form_count())
  File "/usr/local/lib/python3.10/site-packages/django/forms/formsets.py", line 182, in total_form_count
    initial_forms = self.initial_form_count()
  File "/usr/local/lib/python3.10/site-packages/django/forms/models.py", line 1117, in initial_form_count
    return super().initial_form_count()
  File "/usr/local/lib/python3.10/site-packages/django/forms/models.py", line 694, in initial_form_count
    return len(self.get_queryset())
  File "/usr/local/lib/python3.10/site-packages/django/db/models/query.py", line 380, in __len__
    self._fetch_all()
  File "/usr/local/lib/python3.10/site-packages/django/db/models/query.py", line 1926, in _fetch_all
    self._result_cache = list(self._iterable_class(self))
  File "/usr/local/lib/python3.10/site-packages/django/db/models/query.py", line 91, in __iter__
    results = compiler.execute_sql(
  File "/usr/local/lib/python3.10/site-packages/django/db/models/sql/compiler.py", line 1562, in execute_sql
    cursor.execute(sql, params)
  File "/usr/local/lib/python3.10/site-packages/django/db/backends/utils.py", line 122, in execute
    return super().execute(sql, params)
  File "/usr/local/lib/python3.10/site-packages/django/db/backends/utils.py", line 79, in execute
    return self._execute_with_wrappers(
  File "/usr/local/lib/python3.10/site-packages/django/db/backends/utils.py", line 92, in _execute_with_wrappers
    return executor(sql, params, many, context)
  File "/usr/local/lib/python3.10/site-packages/django/db/backends/utils.py", line 100, in _execute
    with self.db.wrap_database_errors:
  File "/usr/local/lib/python3.10/site-packages/django/db/utils.py", line 91, in __exit__
    raise dj_exc_value.with_traceback(traceback) from exc_value
  File "/usr/local/lib/python3.10/site-packages/django/db/backends/utils.py", line 105, in _execute
    return self.cursor.execute(sql, params)
django.db.utils.ProgrammingError: relation "storage_file" does not exist
LINE 1: ...pload_datetime", "storage_file"."by_user_id" FROM "storage_f...
                                                             ^

2024-11-19 09:31:59,977 ERROR django.server "GET /admin/accounts/user/2/change/ HTTP/1.1" 500 196945
2024-11-19 09:32:01,435 INFO django.server "GET /admin/accounts/user/add/ HTTP/1.1" 200 14744
2024-11-19 09:32:24,261 INFO django.server "POST /admin/accounts/user/add/ HTTP/1.1" 302 0
2024-11-19 09:32:24,331 INFO django.server "GET /admin/accounts/user/add/ HTTP/1.1" 200 14975
2024-11-19 09:32:24,395 INFO django.server "GET /admin/jsi18n/ HTTP/1.1" 200 3342
2024-11-19 09:32:24,451 WARNING django.request Not Found: /favicon.ico
2024-11-19 09:32:24,452 WARNING django.server "GET /favicon.ico HTTP/1.1" 404 2979
2024-11-19 09:32:27,013 ERROR django.request Internal Server Error: /admin/accounts/user/3/change/
Traceback (most recent call last):
  File "/usr/local/lib/python3.10/site-packages/django/db/backends/utils.py", line 105, in _execute
    return self.cursor.execute(sql, params)
psycopg2.errors.UndefinedTable: relation "storage_file" does not exist
LINE 1: ...pload_datetime", "storage_file"."by_user_id" FROM "storage_f...
                                                             ^


The above exception was the direct cause of the following exception:

Traceback (most recent call last):
  File "/usr/local/lib/python3.10/site-packages/django/core/handlers/exception.py", line 55, in inner
    response = get_response(request)
  File "/usr/local/lib/python3.10/site-packages/django/core/handlers/base.py", line 197, in _get_response
    response = wrapped_callback(request, *callback_args, **callback_kwargs)
  File "/usr/local/lib/python3.10/site-packages/django/contrib/admin/options.py", line 714, in wrapper
    return self.admin_site.admin_view(view)(*args, **kwargs)
  File "/usr/local/lib/python3.10/site-packages/django/utils/decorators.py", line 188, in _view_wrapper
    result = _process_exception(request, e)
  File "/usr/local/lib/python3.10/site-packages/django/utils/decorators.py", line 186, in _view_wrapper
    response = view_func(request, *args, **kwargs)
  File "/usr/local/lib/python3.10/site-packages/django/views/decorators/cache.py", line 80, in _view_wrapper
    response = view_func(request, *args, **kwargs)
  File "/usr/local/lib/python3.10/site-packages/django/contrib/admin/sites.py", line 240, in inner
    return view(request, *args, **kwargs)
  File "/usr/local/lib/python3.10/site-packages/django/contrib/admin/options.py", line 1944, in change_view
    return self.changeform_view(request, object_id, form_url, extra_context)
  File "/usr/local/lib/python3.10/site-packages/django/utils/decorators.py", line 48, in _wrapper
    return bound_method(*args, **kwargs)
  File "/usr/local/lib/python3.10/site-packages/django/utils/decorators.py", line 188, in _view_wrapper
    result = _process_exception(request, e)
  File "/usr/local/lib/python3.10/site-packages/django/utils/decorators.py", line 186, in _view_wrapper
    response = view_func(request, *args, **kwargs)
  File "/usr/local/lib/python3.10/site-packages/django/contrib/admin/options.py", line 1802, in changeform_view
    return self._changeform_view(request, object_id, form_url, extra_context)
  File "/usr/local/lib/python3.10/site-packages/django/contrib/admin/options.py", line 1899, in _changeform_view
    media += inline_formset.media
  File "/usr/local/lib/python3.10/site-packages/django/contrib/admin/helpers.py", line 454, in media
    media = self.opts.media + self.formset.media
  File "/usr/local/lib/python3.10/site-packages/django/forms/formsets.py", line 521, in media
    if self.forms:
  File "/usr/local/lib/python3.10/site-packages/django/utils/functional.py", line 47, in __get__
    res = instance.__dict__[self.name] = self.func(instance)
  File "/usr/local/lib/python3.10/site-packages/django/forms/formsets.py", line 207, in forms
    for i in range(self.total_form_count())
  File "/usr/local/lib/python3.10/site-packages/django/forms/formsets.py", line 182, in total_form_count
    initial_forms = self.initial_form_count()
  File "/usr/local/lib/python3.10/site-packages/django/forms/models.py", line 1117, in initial_form_count
    return super().initial_form_count()
  File "/usr/local/lib/python3.10/site-packages/django/forms/models.py", line 694, in initial_form_count
    return len(self.get_queryset())
  File "/usr/local/lib/python3.10/site-packages/django/db/models/query.py", line 380, in __len__
    self._fetch_all()
  File "/usr/local/lib/python3.10/site-packages/django/db/models/query.py", line 1926, in _fetch_all
    self._result_cache = list(self._iterable_class(self))
  File "/usr/local/lib/python3.10/site-packages/django/db/models/query.py", line 91, in __iter__
    results = compiler.execute_sql(
  File "/usr/local/lib/python3.10/site-packages/django/db/models/sql/compiler.py", line 1562, in execute_sql
    cursor.execute(sql, params)
  File "/usr/local/lib/python3.10/site-packages/django/db/backends/utils.py", line 122, in execute
    return super().execute(sql, params)
  File "/usr/local/lib/python3.10/site-packages/django/db/backends/utils.py", line 79, in execute
    return self._execute_with_wrappers(
  File "/usr/local/lib/python3.10/site-packages/django/db/backends/utils.py", line 92, in _execute_with_wrappers
    return executor(sql, params, many, context)
  File "/usr/local/lib/python3.10/site-packages/django/db/backends/utils.py", line 100, in _execute
    with self.db.wrap_database_errors:
  File "/usr/local/lib/python3.10/site-packages/django/db/utils.py", line 91, in __exit__
    raise dj_exc_value.with_traceback(traceback) from exc_value
  File "/usr/local/lib/python3.10/site-packages/django/db/backends/utils.py", line 105, in _execute
    return self.cursor.execute(sql, params)
django.db.utils.ProgrammingError: relation "storage_file" does not exist
LINE 1: ...pload_datetime", "storage_file"."by_user_id" FROM "storage_f...
                                                             ^

2024-11-19 09:32:27,014 ERROR django.server "GET /admin/accounts/user/3/change/ HTTP/1.1" 500 196946
2024-11-19 09:32:30,351 INFO django.server "GET /admin/accounts/user/add/ HTTP/1.1" 200 14744
2024-11-19 09:32:30,409 INFO django.server "GET /static/admin/js/prepopulate_init.js HTTP/1.1" 200 586
2024-11-19 09:32:30,410 INFO django.server "GET /static/admin/js/change_form.js HTTP/1.1" 200 606
2024-11-19 09:32:31,334 ERROR django.request Internal Server Error: /admin/accounts/user/
Traceback (most recent call last):
  File "/usr/local/lib/python3.10/site-packages/django/db/models/options.py", line 681, in get_field
    return self.fields_map[field_name]
KeyError: 'file_count'

During handling of the above exception, another exception occurred:

Traceback (most recent call last):
  File "/usr/local/lib/python3.10/site-packages/django/contrib/admin/utils.py", line 289, in lookup_field
    f = _get_non_gfk_field(opts, name)
  File "/usr/local/lib/python3.10/site-packages/django/contrib/admin/utils.py", line 322, in _get_non_gfk_field
    field = opts.get_field(name)
  File "/usr/local/lib/python3.10/site-packages/django/db/models/options.py", line 683, in get_field
    raise FieldDoesNotExist(
django.core.exceptions.FieldDoesNotExist: User has no field named 'file_count'

During handling of the above exception, another exception occurred:

Traceback (most recent call last):
  File "/usr/local/lib/python3.10/site-packages/django/db/backends/utils.py", line 105, in _execute
    return self.cursor.execute(sql, params)
psycopg2.errors.UndefinedTable: relation "storage_file" does not exist
LINE 1: SELECT COUNT(*) AS "__count" FROM "storage_file" WHERE "stor...
                                          ^


The above exception was the direct cause of the following exception:

Traceback (most recent call last):
  File "/usr/local/lib/python3.10/site-packages/django/core/handlers/exception.py", line 55, in inner
    response = get_response(request)
  File "/usr/local/lib/python3.10/site-packages/django/core/handlers/base.py", line 220, in _get_response
    response = response.render()
  File "/usr/local/lib/python3.10/site-packages/django/template/response.py", line 114, in render
    self.content = self.rendered_content
  File "/usr/local/lib/python3.10/site-packages/django/template/response.py", line 92, in rendered_content
    return template.render(context, self._request)
  File "/usr/local/lib/python3.10/site-packages/django/template/backends/django.py", line 61, in render
    return self.template.render(context)
  File "/usr/local/lib/python3.10/site-packages/django/template/base.py", line 171, in render
    return self._render(context)
  File "/usr/local/lib/python3.10/site-packages/django/template/base.py", line 163, in _render
    return self.nodelist.render(context)
  File "/usr/local/lib/python3.10/site-packages/django/template/base.py", line 1000, in render
    return SafeString("".join([node.render_annotated(context) for node in self]))
  File "/usr/local/lib/python3.10/site-packages/django/template/base.py", line 1000, in <listcomp>
    return SafeString("".join([node.render_annotated(context) for node in self]))
  File "/usr/local/lib/python3.10/site-packages/django/template/base.py", line 961, in render_annotated
    return self.render(context)
  File "/usr/local/lib/python3.10/site-packages/django/template/loader_tags.py", line 159, in render
    return compiled_parent._render(context)
  File "/usr/local/lib/python3.10/site-packages/django/template/base.py", line 163, in _render
    return self.nodelist.render(context)
  File "/usr/local/lib/python3.10/site-packages/django/template/base.py", line 1000, in render
    return SafeString("".join([node.render_annotated(context) for node in self]))
  File "/usr/local/lib/python3.10/site-packages/django/template/base.py", line 1000, in <listcomp>
    return SafeString("".join([node.render_annotated(context) for node in self]))
  File "/usr/local/lib/python3.10/site-packages/django/template/base.py", line 961, in render_annotated
    return self.render(context)
  File "/usr/local/lib/python3.10/site-packages/django/template/loader_tags.py", line 159, in render
    return compiled_parent._render(context)
  File "/usr/local/lib/python3.10/site-packages/django/template/base.py", line 163, in _render
    return self.nodelist.render(context)
  File "/usr/local/lib/python3.10/site-packages/django/template/base.py", line 1000, in render
    return SafeString("".join([node.render_annotated(context) for node in self]))
  File "/usr/local/lib/python3.10/site-packages/django/template/base.py", line 1000, in <listcomp>
    return SafeString("".join([node.render_annotated(context) for node in self]))
  File "/usr/local/lib/python3.10/site-packages/django/template/base.py", line 961, in render_annotated
    return self.render(context)
  File "/usr/local/lib/python3.10/site-packages/django/template/loader_tags.py", line 65, in render
    result = block.nodelist.render(context)
  File "/usr/local/lib/python3.10/site-packages/django/template/base.py", line 1000, in render
    return SafeString("".join([node.render_annotated(context) for node in self]))
  File "/usr/local/lib/python3.10/site-packages/django/template/base.py", line 1000, in <listcomp>
    return SafeString("".join([node.render_annotated(context) for node in self]))
  File "/usr/local/lib/python3.10/site-packages/django/template/base.py", line 961, in render_annotated
    return self.render(context)
  File "/usr/local/lib/python3.10/site-packages/django/template/loader_tags.py", line 65, in render
    result = block.nodelist.render(context)
  File "/usr/local/lib/python3.10/site-packages/django/template/base.py", line 1000, in render
    return SafeString("".join([node.render_annotated(context) for node in self]))
  File "/usr/local/lib/python3.10/site-packages/django/template/base.py", line 1000, in <listcomp>
    return SafeString("".join([node.render_annotated(context) for node in self]))
  File "/usr/local/lib/python3.10/site-packages/django/template/base.py", line 961, in render_annotated
    return self.render(context)
  File "/usr/local/lib/python3.10/site-packages/django/contrib/admin/templatetags/base.py", line 45, in render
    return super().render(context)
  File "/usr/local/lib/python3.10/site-packages/django/template/library.py", line 258, in render
    _dict = self.func(*resolved_args, **resolved_kwargs)
  File "/usr/local/lib/python3.10/site-packages/django/contrib/admin/templatetags/admin_list.py", line 343, in result_list
    "results": list(results(cl)),
  File "/usr/local/lib/python3.10/site-packages/django/contrib/admin/templatetags/admin_list.py", line 319, in results
    yield ResultList(None, items_for_result(cl, res, None))
  File "/usr/local/lib/python3.10/site-packages/django/contrib/admin/templatetags/admin_list.py", line 310, in __init__
    super().__init__(*items)
  File "/usr/local/lib/python3.10/site-packages/django/contrib/admin/templatetags/admin_list.py", line 217, in items_for_result
    f, attr, value = lookup_field(field_name, result, cl.model_admin)
  File "/usr/local/lib/python3.10/site-packages/django/contrib/admin/utils.py", line 298, in lookup_field
    value = attr(obj)
  File "/app/accounts/admin.py", line 35, in file_count
    return obj.file_set.count()
  File "/usr/local/lib/python3.10/site-packages/django/db/models/manager.py", line 87, in manager_method
    return getattr(self.get_queryset(), name)(*args, **kwargs)
  File "/usr/local/lib/python3.10/site-packages/django/db/models/query.py", line 618, in count
    return self.query.get_count(using=self.db)
  File "/usr/local/lib/python3.10/site-packages/django/db/models/sql/query.py", line 616, in get_count
    return obj.get_aggregation(using, {"__count": Count("*")})["__count"]
  File "/usr/local/lib/python3.10/site-packages/django/db/models/sql/query.py", line 602, in get_aggregation
    result = compiler.execute_sql(SINGLE)
  File "/usr/local/lib/python3.10/site-packages/django/db/models/sql/compiler.py", line 1562, in execute_sql
    cursor.execute(sql, params)
  File "/usr/local/lib/python3.10/site-packages/django/db/backends/utils.py", line 122, in execute
    return super().execute(sql, params)
  File "/usr/local/lib/python3.10/site-packages/django/db/backends/utils.py", line 79, in execute
    return self._execute_with_wrappers(
  File "/usr/local/lib/python3.10/site-packages/django/db/backends/utils.py", line 92, in _execute_with_wrappers
    return executor(sql, params, many, context)
  File "/usr/local/lib/python3.10/site-packages/django/db/backends/utils.py", line 100, in _execute
    with self.db.wrap_database_errors:
  File "/usr/local/lib/python3.10/site-packages/django/db/utils.py", line 91, in __exit__
    raise dj_exc_value.with_traceback(traceback) from exc_value
  File "/usr/local/lib/python3.10/site-packages/django/db/backends/utils.py", line 105, in _execute
    return self.cursor.execute(sql, params)
django.db.utils.ProgrammingError: relation "storage_file" does not exist
LINE 1: SELECT COUNT(*) AS "__count" FROM "storage_file" WHERE "stor...
                                          ^

2024-11-19 09:32:31,337 ERROR django.server "GET /admin/accounts/user/ HTTP/1.1" 500 415344
2024-11-19 09:32:35,653 INFO django.server "GET /admin/accounts/user/add/ HTTP/1.1" 200 14744
2024-11-19 09:32:37,053 ERROR django.request Internal Server Error: /admin/storage/file/
Traceback (most recent call last):
  File "/usr/local/lib/python3.10/site-packages/django/db/backends/utils.py", line 105, in _execute
    return self.cursor.execute(sql, params)
psycopg2.errors.UndefinedTable: relation "storage_file" does not exist
LINE 1: SELECT COUNT(*) AS "__count" FROM "storage_file"
                                          ^


The above exception was the direct cause of the following exception:

Traceback (most recent call last):
  File "/usr/local/lib/python3.10/site-packages/django/core/handlers/exception.py", line 55, in inner
    response = get_response(request)
  File "/usr/local/lib/python3.10/site-packages/django/core/handlers/base.py", line 197, in _get_response
    response = wrapped_callback(request, *callback_args, **callback_kwargs)
  File "/usr/local/lib/python3.10/site-packages/django/contrib/admin/options.py", line 714, in wrapper
    return self.admin_site.admin_view(view)(*args, **kwargs)
  File "/usr/local/lib/python3.10/site-packages/django/utils/decorators.py", line 188, in _view_wrapper
    result = _process_exception(request, e)
  File "/usr/local/lib/python3.10/site-packages/django/utils/decorators.py", line 186, in _view_wrapper
    response = view_func(request, *args, **kwargs)
  File "/usr/local/lib/python3.10/site-packages/django/views/decorators/cache.py", line 80, in _view_wrapper
    response = view_func(request, *args, **kwargs)
  File "/usr/local/lib/python3.10/site-packages/django/contrib/admin/sites.py", line 240, in inner
    return view(request, *args, **kwargs)
  File "/usr/local/lib/python3.10/site-packages/django/utils/decorators.py", line 48, in _wrapper
    return bound_method(*args, **kwargs)
  File "/usr/local/lib/python3.10/site-packages/django/utils/decorators.py", line 188, in _view_wrapper
    result = _process_exception(request, e)
  File "/usr/local/lib/python3.10/site-packages/django/utils/decorators.py", line 186, in _view_wrapper
    response = view_func(request, *args, **kwargs)
  File "/usr/local/lib/python3.10/site-packages/django/contrib/admin/options.py", line 1981, in changelist_view
    cl = self.get_changelist_instance(request)
  File "/usr/local/lib/python3.10/site-packages/django/contrib/admin/options.py", line 862, in get_changelist_instance
    return ChangeList(
  File "/usr/local/lib/python3.10/site-packages/django/contrib/admin/views/main.py", line 145, in __init__
    self.get_results(request)
  File "/usr/local/lib/python3.10/site-packages/django/contrib/admin/views/main.py", line 312, in get_results
    result_count = paginator.count
  File "/usr/local/lib/python3.10/site-packages/django/utils/functional.py", line 47, in __get__
    res = instance.__dict__[self.name] = self.func(instance)
  File "/usr/local/lib/python3.10/site-packages/django/core/paginator.py", line 110, in count
    return c()
  File "/usr/local/lib/python3.10/site-packages/django/db/models/query.py", line 618, in count
    return self.query.get_count(using=self.db)
  File "/usr/local/lib/python3.10/site-packages/django/db/models/sql/query.py", line 616, in get_count
    return obj.get_aggregation(using, {"__count": Count("*")})["__count"]
  File "/usr/local/lib/python3.10/site-packages/django/db/models/sql/query.py", line 602, in get_aggregation
    result = compiler.execute_sql(SINGLE)
  File "/usr/local/lib/python3.10/site-packages/django/db/models/sql/compiler.py", line 1562, in execute_sql
    cursor.execute(sql, params)
  File "/usr/local/lib/python3.10/site-packages/django/db/backends/utils.py", line 122, in execute
    return super().execute(sql, params)
  File "/usr/local/lib/python3.10/site-packages/django/db/backends/utils.py", line 79, in execute
    return self._execute_with_wrappers(
  File "/usr/local/lib/python3.10/site-packages/django/db/backends/utils.py", line 92, in _execute_with_wrappers
    return executor(sql, params, many, context)
  File "/usr/local/lib/python3.10/site-packages/django/db/backends/utils.py", line 100, in _execute
    with self.db.wrap_database_errors:
  File "/usr/local/lib/python3.10/site-packages/django/db/utils.py", line 91, in __exit__
    raise dj_exc_value.with_traceback(traceback) from exc_value
  File "/usr/local/lib/python3.10/site-packages/django/db/backends/utils.py", line 105, in _execute
    return self.cursor.execute(sql, params)
django.db.utils.ProgrammingError: relation "storage_file" does not exist
LINE 1: SELECT COUNT(*) AS "__count" FROM "storage_file"
                                          ^

2024-11-19 09:32:37,054 ERROR django.server "GET /admin/storage/file/ HTTP/1.1" 500 179449
2024-11-19 09:32:42,712 INFO django.server "GET /admin/accounts/user/add/ HTTP/1.1" 200 14744
2024-11-19 09:32:44,247 INFO django.server "GET /admin/storage/ HTTP/1.1" 200 5037
2024-11-19 09:32:45,671 INFO django.server "GET /admin/storage/file/add/ HTTP/1.1" 200 13653
2024-11-19 09:32:45,720 INFO django.server "GET /admin/jsi18n/ HTTP/1.1" 200 3342
2024-11-19 09:32:57,073 ERROR django.request Internal Server Error: /admin/storage/file/add/
Traceback (most recent call last):
  File "/usr/local/lib/python3.10/site-packages/django/db/backends/utils.py", line 105, in _execute
    return self.cursor.execute(sql, params)
psycopg2.errors.UndefinedTable: relation "storage_file" does not exist
LINE 1: ...pload_datetime", "storage_file"."by_user_id" FROM "storage_f...
                                                             ^


The above exception was the direct cause of the following exception:

Traceback (most recent call last):
  File "/usr/local/lib/python3.10/site-packages/django/core/handlers/exception.py", line 55, in inner
    response = get_response(request)
  File "/usr/local/lib/python3.10/site-packages/django/core/handlers/base.py", line 197, in _get_response
    response = wrapped_callback(request, *callback_args, **callback_kwargs)
  File "/usr/local/lib/python3.10/site-packages/django/contrib/admin/options.py", line 714, in wrapper
    return self.admin_site.admin_view(view)(*args, **kwargs)
  File "/usr/local/lib/python3.10/site-packages/django/utils/decorators.py", line 188, in _view_wrapper
    result = _process_exception(request, e)
  File "/usr/local/lib/python3.10/site-packages/django/utils/decorators.py", line 186, in _view_wrapper
    response = view_func(request, *args, **kwargs)
  File "/usr/local/lib/python3.10/site-packages/django/views/decorators/cache.py", line 80, in _view_wrapper
    response = view_func(request, *args, **kwargs)
  File "/usr/local/lib/python3.10/site-packages/django/contrib/admin/sites.py", line 240, in inner
    return view(request, *args, **kwargs)
  File "/usr/local/lib/python3.10/site-packages/django/contrib/admin/options.py", line 1941, in add_view
    return self.changeform_view(request, None, form_url, extra_context)
  File "/usr/local/lib/python3.10/site-packages/django/utils/decorators.py", line 48, in _wrapper
    return bound_method(*args, **kwargs)
  File "/usr/local/lib/python3.10/site-packages/django/utils/decorators.py", line 188, in _view_wrapper
    result = _process_exception(request, e)
  File "/usr/local/lib/python3.10/site-packages/django/utils/decorators.py", line 186, in _view_wrapper
    response = view_func(request, *args, **kwargs)
  File "/usr/local/lib/python3.10/site-packages/django/contrib/admin/options.py", line 1802, in changeform_view
    return self._changeform_view(request, object_id, form_url, extra_context)
  File "/usr/local/lib/python3.10/site-packages/django/contrib/admin/options.py", line 1853, in _changeform_view
    self.save_model(request, new_object, form, not add)
  File "/usr/local/lib/python3.10/site-packages/django/contrib/admin/options.py", line 1257, in save_model
    obj.save()
  File "/app/storage/models.py", line 67, in save
    self.filename = check_unique_filename(userfolder, f'{self.filename}{file_ext}')
  File "/app/storage/models.py", line 22, in check_unique_filename
    if File.objects.filter(file=new_filepath):
  File "/usr/local/lib/python3.10/site-packages/django/db/models/query.py", line 412, in __bool__
    self._fetch_all()
  File "/usr/local/lib/python3.10/site-packages/django/db/models/query.py", line 1926, in _fetch_all
    self._result_cache = list(self._iterable_class(self))
  File "/usr/local/lib/python3.10/site-packages/django/db/models/query.py", line 91, in __iter__
    results = compiler.execute_sql(
  File "/usr/local/lib/python3.10/site-packages/django/db/models/sql/compiler.py", line 1562, in execute_sql
    cursor.execute(sql, params)
  File "/usr/local/lib/python3.10/site-packages/django/db/backends/utils.py", line 122, in execute
    return super().execute(sql, params)
  File "/usr/local/lib/python3.10/site-packages/django/db/backends/utils.py", line 79, in execute
    return self._execute_with_wrappers(
  File "/usr/local/lib/python3.10/site-packages/django/db/backends/utils.py", line 92, in _execute_with_wrappers
    return executor(sql, params, many, context)
  File "/usr/local/lib/python3.10/site-packages/django/db/backends/utils.py", line 100, in _execute
    with self.db.wrap_database_errors:
  File "/usr/local/lib/python3.10/site-packages/django/db/utils.py", line 91, in __exit__
    raise dj_exc_value.with_traceback(traceback) from exc_value
  File "/usr/local/lib/python3.10/site-packages/django/db/backends/utils.py", line 105, in _execute
    return self.cursor.execute(sql, params)
django.db.utils.ProgrammingError: relation "storage_file" does not exist
LINE 1: ...pload_datetime", "storage_file"."by_user_id" FROM "storage_f...
                                                             ^

2024-11-19 09:32:57,074 ERROR django.server "POST /admin/storage/file/add/ HTTP/1.1" 500 182599
2024-11-19 09:33:05,061 INFO django.server "GET /admin/storage/file/add/ HTTP/1.1" 200 13653
2024-11-19 09:33:07,514 INFO django.server "GET /admin/storage/ HTTP/1.1" 200 5037
2024-11-19 09:33:08,162 INFO django.server "GET /admin/accounts/user/add/ HTTP/1.1" 200 14744
2024-11-19 09:33:08,653 INFO django.server "GET /admin/ HTTP/1.1" 200 7149
2024-11-19 09:33:09,009 INFO django.server "GET /admin/login/?next=/admin/ HTTP/1.1" 302 0
2024-11-19 09:33:09,032 INFO django.server "GET /admin/ HTTP/1.1" 200 7149
2024-11-19 09:33:12,862 WARNING django.request Unauthorized: /api/
2024-11-19 09:33:12,862 WARNING django.server "GET /api/ HTTP/1.1" 401 5019
2024-11-19 09:33:17,960 INFO django.server "GET /admin/ HTTP/1.1" 200 7149
2024-11-19 09:33:20,710 INFO django.server "GET /admin/authtoken/ HTTP/1.1" 200 5089
2024-11-19 09:33:21,831 INFO django.server "GET /admin/authtoken/tokenproxy/add/ HTTP/1.1" 200 9539
2024-11-19 09:33:21,888 INFO django.server "GET /admin/jsi18n/ HTTP/1.1" 200 3342
2024-11-19 09:33:24,370 INFO django.server "POST /admin/authtoken/tokenproxy/add/ HTTP/1.1" 302 0
2024-11-19 09:33:24,396 INFO django.server "GET /admin/authtoken/tokenproxy/ HTTP/1.1" 200 8856
2024-11-19 09:33:24,445 INFO django.server "GET /static/admin/css/changelists.css HTTP/1.1" 200 6811
2024-11-19 09:33:24,447 INFO django.server "GET /static/admin/js/filters.js HTTP/1.1" 200 978
2024-11-19 09:33:24,473 INFO django.server "GET /static/admin/img/sorting-icons.svg HTTP/1.1" 200 1097
2024-11-19 09:33:29,741 WARNING django.request Unauthorized: /api/
2024-11-19 09:33:29,742 WARNING django.server "GET /api/ HTTP/1.1" 401 5019
2024-11-19 09:33:31,907 WARNING django.request Unauthorized: /api/
2024-11-19 09:33:31,907 WARNING django.server "GET /api/ HTTP/1.1" 401 5019
2024-11-19 09:33:33,349 INFO django.server "GET /admin/authtoken/tokenproxy/ HTTP/1.1" 200 8618
2024-11-19 09:33:33,713 INFO django.server "GET /admin/authtoken/tokenproxy/add/ HTTP/1.1" 200 9539
2024-11-19 09:33:34,721 INFO django.server "GET /admin/authtoken/tokenproxy/ HTTP/1.1" 200 8618
2024-11-19 09:33:35,935 INFO django.server "GET /admin/authtoken/tokenproxy/ HTTP/1.1" 200 8618
2024-11-19 09:33:36,491 INFO django.server "GET /admin/authtoken/tokenproxy/ HTTP/1.1" 200 8618
2024-11-19 09:33:36,822 INFO django.server "GET /admin/authtoken/tokenproxy/ HTTP/1.1" 200 8618
2024-11-19 09:33:37,123 INFO django.server "GET /admin/authtoken/tokenproxy/ HTTP/1.1" 200 8618
2024-11-19 09:33:39,924 ERROR django.request Internal Server Error: /admin/accounts/user/
Traceback (most recent call last):
  File "/usr/local/lib/python3.10/site-packages/django/db/models/options.py", line 681, in get_field
    return self.fields_map[field_name]
KeyError: 'file_count'

During handling of the above exception, another exception occurred:

Traceback (most recent call last):
  File "/usr/local/lib/python3.10/site-packages/django/contrib/admin/utils.py", line 289, in lookup_field
    f = _get_non_gfk_field(opts, name)
  File "/usr/local/lib/python3.10/site-packages/django/contrib/admin/utils.py", line 322, in _get_non_gfk_field
    field = opts.get_field(name)
  File "/usr/local/lib/python3.10/site-packages/django/db/models/options.py", line 683, in get_field
    raise FieldDoesNotExist(
django.core.exceptions.FieldDoesNotExist: User has no field named 'file_count'

During handling of the above exception, another exception occurred:

Traceback (most recent call last):
  File "/usr/local/lib/python3.10/site-packages/django/db/backends/utils.py", line 105, in _execute
    return self.cursor.execute(sql, params)
psycopg2.errors.UndefinedTable: relation "storage_file" does not exist
LINE 1: SELECT COUNT(*) AS "__count" FROM "storage_file" WHERE "stor...
                                          ^


The above exception was the direct cause of the following exception:

Traceback (most recent call last):
  File "/usr/local/lib/python3.10/site-packages/django/core/handlers/exception.py", line 55, in inner
    response = get_response(request)
  File "/usr/local/lib/python3.10/site-packages/django/core/handlers/base.py", line 220, in _get_response
    response = response.render()
  File "/usr/local/lib/python3.10/site-packages/django/template/response.py", line 114, in render
    self.content = self.rendered_content
  File "/usr/local/lib/python3.10/site-packages/django/template/response.py", line 92, in rendered_content
    return template.render(context, self._request)
  File "/usr/local/lib/python3.10/site-packages/django/template/backends/django.py", line 61, in render
    return self.template.render(context)
  File "/usr/local/lib/python3.10/site-packages/django/template/base.py", line 171, in render
    return self._render(context)
  File "/usr/local/lib/python3.10/site-packages/django/template/base.py", line 163, in _render
    return self.nodelist.render(context)
  File "/usr/local/lib/python3.10/site-packages/django/template/base.py", line 1000, in render
    return SafeString("".join([node.render_annotated(context) for node in self]))
  File "/usr/local/lib/python3.10/site-packages/django/template/base.py", line 1000, in <listcomp>
    return SafeString("".join([node.render_annotated(context) for node in self]))
  File "/usr/local/lib/python3.10/site-packages/django/template/base.py", line 961, in render_annotated
    return self.render(context)
  File "/usr/local/lib/python3.10/site-packages/django/template/loader_tags.py", line 159, in render
    return compiled_parent._render(context)
  File "/usr/local/lib/python3.10/site-packages/django/template/base.py", line 163, in _render
    return self.nodelist.render(context)
  File "/usr/local/lib/python3.10/site-packages/django/template/base.py", line 1000, in render
    return SafeString("".join([node.render_annotated(context) for node in self]))
  File "/usr/local/lib/python3.10/site-packages/django/template/base.py", line 1000, in <listcomp>
    return SafeString("".join([node.render_annotated(context) for node in self]))
  File "/usr/local/lib/python3.10/site-packages/django/template/base.py", line 961, in render_annotated
    return self.render(context)
  File "/usr/local/lib/python3.10/site-packages/django/template/loader_tags.py", line 159, in render
    return compiled_parent._render(context)
  File "/usr/local/lib/python3.10/site-packages/django/template/base.py", line 163, in _render
    return self.nodelist.render(context)
  File "/usr/local/lib/python3.10/site-packages/django/template/base.py", line 1000, in render
    return SafeString("".join([node.render_annotated(context) for node in self]))
  File "/usr/local/lib/python3.10/site-packages/django/template/base.py", line 1000, in <listcomp>
    return SafeString("".join([node.render_annotated(context) for node in self]))
  File "/usr/local/lib/python3.10/site-packages/django/template/base.py", line 961, in render_annotated
    return self.render(context)
  File "/usr/local/lib/python3.10/site-packages/django/template/loader_tags.py", line 65, in render
    result = block.nodelist.render(context)
  File "/usr/local/lib/python3.10/site-packages/django/template/base.py", line 1000, in render
    return SafeString("".join([node.render_annotated(context) for node in self]))
  File "/usr/local/lib/python3.10/site-packages/django/template/base.py", line 1000, in <listcomp>
    return SafeString("".join([node.render_annotated(context) for node in self]))
  File "/usr/local/lib/python3.10/site-packages/django/template/base.py", line 961, in render_annotated
    return self.render(context)
  File "/usr/local/lib/python3.10/site-packages/django/template/loader_tags.py", line 65, in render
    result = block.nodelist.render(context)
  File "/usr/local/lib/python3.10/site-packages/django/template/base.py", line 1000, in render
    return SafeString("".join([node.render_annotated(context) for node in self]))
  File "/usr/local/lib/python3.10/site-packages/django/template/base.py", line 1000, in <listcomp>
    return SafeString("".join([node.render_annotated(context) for node in self]))
  File "/usr/local/lib/python3.10/site-packages/django/template/base.py", line 961, in render_annotated
    return self.render(context)
  File "/usr/local/lib/python3.10/site-packages/django/contrib/admin/templatetags/base.py", line 45, in render
    return super().render(context)
  File "/usr/local/lib/python3.10/site-packages/django/template/library.py", line 258, in render
    _dict = self.func(*resolved_args, **resolved_kwargs)
  File "/usr/local/lib/python3.10/site-packages/django/contrib/admin/templatetags/admin_list.py", line 343, in result_list
    "results": list(results(cl)),
  File "/usr/local/lib/python3.10/site-packages/django/contrib/admin/templatetags/admin_list.py", line 319, in results
    yield ResultList(None, items_for_result(cl, res, None))
  File "/usr/local/lib/python3.10/site-packages/django/contrib/admin/templatetags/admin_list.py", line 310, in __init__
    super().__init__(*items)
  File "/usr/local/lib/python3.10/site-packages/django/contrib/admin/templatetags/admin_list.py", line 217, in items_for_result
    f, attr, value = lookup_field(field_name, result, cl.model_admin)
  File "/usr/local/lib/python3.10/site-packages/django/contrib/admin/utils.py", line 298, in lookup_field
    value = attr(obj)
  File "/app/accounts/admin.py", line 35, in file_count
    return obj.file_set.count()
  File "/usr/local/lib/python3.10/site-packages/django/db/models/manager.py", line 87, in manager_method
    return getattr(self.get_queryset(), name)(*args, **kwargs)
  File "/usr/local/lib/python3.10/site-packages/django/db/models/query.py", line 618, in count
    return self.query.get_count(using=self.db)
  File "/usr/local/lib/python3.10/site-packages/django/db/models/sql/query.py", line 616, in get_count
    return obj.get_aggregation(using, {"__count": Count("*")})["__count"]
  File "/usr/local/lib/python3.10/site-packages/django/db/models/sql/query.py", line 602, in get_aggregation
    result = compiler.execute_sql(SINGLE)
  File "/usr/local/lib/python3.10/site-packages/django/db/models/sql/compiler.py", line 1562, in execute_sql
    cursor.execute(sql, params)
  File "/usr/local/lib/python3.10/site-packages/django/db/backends/utils.py", line 122, in execute
    return super().execute(sql, params)
  File "/usr/local/lib/python3.10/site-packages/django/db/backends/utils.py", line 79, in execute
    return self._execute_with_wrappers(
  File "/usr/local/lib/python3.10/site-packages/django/db/backends/utils.py", line 92, in _execute_with_wrappers
    return executor(sql, params, many, context)
  File "/usr/local/lib/python3.10/site-packages/django/db/backends/utils.py", line 100, in _execute
    with self.db.wrap_database_errors:
  File "/usr/local/lib/python3.10/site-packages/django/db/utils.py", line 91, in __exit__
    raise dj_exc_value.with_traceback(traceback) from exc_value
  File "/usr/local/lib/python3.10/site-packages/django/db/backends/utils.py", line 105, in _execute
    return self.cursor.execute(sql, params)
django.db.utils.ProgrammingError: relation "storage_file" does not exist
LINE 1: SELECT COUNT(*) AS "__count" FROM "storage_file" WHERE "stor...
                                          ^

2024-11-19 09:33:39,925 ERROR django.server "GET /admin/accounts/user/ HTTP/1.1" 500 416265
2024-11-19 09:33:41,316 INFO django.server "GET /admin/authtoken/tokenproxy/ HTTP/1.1" 200 8618
2024-11-19 09:33:42,205 ERROR django.request Internal Server Error: /admin/storage/file/
Traceback (most recent call last):
  File "/usr/local/lib/python3.10/site-packages/django/db/backends/utils.py", line 105, in _execute
    return self.cursor.execute(sql, params)
psycopg2.errors.UndefinedTable: relation "storage_file" does not exist
LINE 1: SELECT COUNT(*) AS "__count" FROM "storage_file"
                                          ^


The above exception was the direct cause of the following exception:

Traceback (most recent call last):
  File "/usr/local/lib/python3.10/site-packages/django/core/handlers/exception.py", line 55, in inner
    response = get_response(request)
  File "/usr/local/lib/python3.10/site-packages/django/core/handlers/base.py", line 197, in _get_response
    response = wrapped_callback(request, *callback_args, **callback_kwargs)
  File "/usr/local/lib/python3.10/site-packages/django/contrib/admin/options.py", line 714, in wrapper
    return self.admin_site.admin_view(view)(*args, **kwargs)
  File "/usr/local/lib/python3.10/site-packages/django/utils/decorators.py", line 188, in _view_wrapper
    result = _process_exception(request, e)
  File "/usr/local/lib/python3.10/site-packages/django/utils/decorators.py", line 186, in _view_wrapper
    response = view_func(request, *args, **kwargs)
  File "/usr/local/lib/python3.10/site-packages/django/views/decorators/cache.py", line 80, in _view_wrapper
    response = view_func(request, *args, **kwargs)
  File "/usr/local/lib/python3.10/site-packages/django/contrib/admin/sites.py", line 240, in inner
    return view(request, *args, **kwargs)
  File "/usr/local/lib/python3.10/site-packages/django/utils/decorators.py", line 48, in _wrapper
    return bound_method(*args, **kwargs)
  File "/usr/local/lib/python3.10/site-packages/django/utils/decorators.py", line 188, in _view_wrapper
    result = _process_exception(request, e)
  File "/usr/local/lib/python3.10/site-packages/django/utils/decorators.py", line 186, in _view_wrapper
    response = view_func(request, *args, **kwargs)
  File "/usr/local/lib/python3.10/site-packages/django/contrib/admin/options.py", line 1981, in changelist_view
    cl = self.get_changelist_instance(request)
  File "/usr/local/lib/python3.10/site-packages/django/contrib/admin/options.py", line 862, in get_changelist_instance
    return ChangeList(
  File "/usr/local/lib/python3.10/site-packages/django/contrib/admin/views/main.py", line 145, in __init__
    self.get_results(request)
  File "/usr/local/lib/python3.10/site-packages/django/contrib/admin/views/main.py", line 312, in get_results
    result_count = paginator.count
  File "/usr/local/lib/python3.10/site-packages/django/utils/functional.py", line 47, in __get__
    res = instance.__dict__[self.name] = self.func(instance)
  File "/usr/local/lib/python3.10/site-packages/django/core/paginator.py", line 110, in count
    return c()
  File "/usr/local/lib/python3.10/site-packages/django/db/models/query.py", line 618, in count
    return self.query.get_count(using=self.db)
  File "/usr/local/lib/python3.10/site-packages/django/db/models/sql/query.py", line 616, in get_count
    return obj.get_aggregation(using, {"__count": Count("*")})["__count"]
  File "/usr/local/lib/python3.10/site-packages/django/db/models/sql/query.py", line 602, in get_aggregation
    result = compiler.execute_sql(SINGLE)
  File "/usr/local/lib/python3.10/site-packages/django/db/models/sql/compiler.py", line 1562, in execute_sql
    cursor.execute(sql, params)
  File "/usr/local/lib/python3.10/site-packages/django/db/backends/utils.py", line 122, in execute
    return super().execute(sql, params)
  File "/usr/local/lib/python3.10/site-packages/django/db/backends/utils.py", line 79, in execute
    return self._execute_with_wrappers(
  File "/usr/local/lib/python3.10/site-packages/django/db/backends/utils.py", line 92, in _execute_with_wrappers
    return executor(sql, params, many, context)
  File "/usr/local/lib/python3.10/site-packages/django/db/backends/utils.py", line 100, in _execute
    with self.db.wrap_database_errors:
  File "/usr/local/lib/python3.10/site-packages/django/db/utils.py", line 91, in __exit__
    raise dj_exc_value.with_traceback(traceback) from exc_value
  File "/usr/local/lib/python3.10/site-packages/django/db/backends/utils.py", line 105, in _execute
    return self.cursor.execute(sql, params)
django.db.utils.ProgrammingError: relation "storage_file" does not exist
LINE 1: SELECT COUNT(*) AS "__count" FROM "storage_file"
                                          ^

2024-11-19 09:33:42,206 ERROR django.server "GET /admin/storage/file/ HTTP/1.1" 500 179452
2024-11-19 09:33:43,328 INFO django.server "GET /admin/authtoken/tokenproxy/ HTTP/1.1" 200 8618
2024-11-19 09:33:47,506 WARNING django.request Not Found: /
2024-11-19 09:33:47,507 WARNING django.server "GET / HTTP/1.1" 404 2928
2024-11-19 09:33:50,929 WARNING django.request Method Not Allowed: /login/
2024-11-19 09:33:50,929 WARNING django.server "GET /login/ HTTP/1.1" 405 5582
2024-11-19 09:33:57,087 WARNING django.request Method Not Allowed: /login/
2024-11-19 09:33:57,087 WARNING django.server "GET /login/ HTTP/1.1" 405 5582
2024-11-19 09:33:58,473 INFO django.server "OPTIONS /login/ HTTP/1.1" 200 5852
2024-11-19 09:34:05,051 WARNING django.request Method Not Allowed: /login/
2024-11-19 09:34:05,052 WARNING django.server "GET /login/ HTTP/1.1" 405 5582
2024-11-19 09:34:07,107 INFO django.server "GET /admin/authtoken/tokenproxy/ HTTP/1.1" 200 8618
2024-11-19 09:34:09,622 INFO django.server "GET /admin/authtoken/tokenproxy/ HTTP/1.1" 200 8618
2024-11-19 09:34:09,783 INFO django.server "GET /admin/authtoken/tokenproxy/add/ HTTP/1.1" 200 9539
2024-11-19 09:34:09,943 INFO django.server "GET /admin/authtoken/ HTTP/1.1" 200 5089
2024-11-19 09:35:17,729 INFO django.server "GET /admin/authtoken/tokenproxy/ HTTP/1.1" 200 8618
2024-11-19 09:35:17,811 WARNING django.request Not Found: /favicon.ico
2024-11-19 09:35:17,811 WARNING django.server "GET /favicon.ico HTTP/1.1" 404 2979
2024-11-19 09:35:19,481 INFO django.server "GET /admin/ HTTP/1.1" 200 7533
2024-11-19 09:35:19,532 WARNING django.request Not Found: /favicon.ico
2024-11-19 09:35:19,532 WARNING django.server "GET /favicon.ico HTTP/1.1" 404 2979
2024-11-19 09:35:20,978 ERROR django.request Internal Server Error: /admin/accounts/user/
Traceback (most recent call last):
  File "/usr/local/lib/python3.10/site-packages/django/db/models/options.py", line 681, in get_field
    return self.fields_map[field_name]
KeyError: 'file_count'

During handling of the above exception, another exception occurred:

Traceback (most recent call last):
  File "/usr/local/lib/python3.10/site-packages/django/contrib/admin/utils.py", line 289, in lookup_field
    f = _get_non_gfk_field(opts, name)
  File "/usr/local/lib/python3.10/site-packages/django/contrib/admin/utils.py", line 322, in _get_non_gfk_field
    field = opts.get_field(name)
  File "/usr/local/lib/python3.10/site-packages/django/db/models/options.py", line 683, in get_field
    raise FieldDoesNotExist(
django.core.exceptions.FieldDoesNotExist: User has no field named 'file_count'

During handling of the above exception, another exception occurred:

Traceback (most recent call last):
  File "/usr/local/lib/python3.10/site-packages/django/db/backends/utils.py", line 105, in _execute
    return self.cursor.execute(sql, params)
psycopg2.errors.UndefinedTable: relation "storage_file" does not exist
LINE 1: SELECT COUNT(*) AS "__count" FROM "storage_file" WHERE "stor...
                                          ^


The above exception was the direct cause of the following exception:

Traceback (most recent call last):
  File "/usr/local/lib/python3.10/site-packages/django/core/handlers/exception.py", line 55, in inner
    response = get_response(request)
  File "/usr/local/lib/python3.10/site-packages/django/core/handlers/base.py", line 220, in _get_response
    response = response.render()
  File "/usr/local/lib/python3.10/site-packages/django/template/response.py", line 114, in render
    self.content = self.rendered_content
  File "/usr/local/lib/python3.10/site-packages/django/template/response.py", line 92, in rendered_content
    return template.render(context, self._request)
  File "/usr/local/lib/python3.10/site-packages/django/template/backends/django.py", line 61, in render
    return self.template.render(context)
  File "/usr/local/lib/python3.10/site-packages/django/template/base.py", line 171, in render
    return self._render(context)
  File "/usr/local/lib/python3.10/site-packages/django/template/base.py", line 163, in _render
    return self.nodelist.render(context)
  File "/usr/local/lib/python3.10/site-packages/django/template/base.py", line 1000, in render
    return SafeString("".join([node.render_annotated(context) for node in self]))
  File "/usr/local/lib/python3.10/site-packages/django/template/base.py", line 1000, in <listcomp>
    return SafeString("".join([node.render_annotated(context) for node in self]))
  File "/usr/local/lib/python3.10/site-packages/django/template/base.py", line 961, in render_annotated
    return self.render(context)
  File "/usr/local/lib/python3.10/site-packages/django/template/loader_tags.py", line 159, in render
    return compiled_parent._render(context)
  File "/usr/local/lib/python3.10/site-packages/django/template/base.py", line 163, in _render
    return self.nodelist.render(context)
  File "/usr/local/lib/python3.10/site-packages/django/template/base.py", line 1000, in render
    return SafeString("".join([node.render_annotated(context) for node in self]))
  File "/usr/local/lib/python3.10/site-packages/django/template/base.py", line 1000, in <listcomp>
    return SafeString("".join([node.render_annotated(context) for node in self]))
  File "/usr/local/lib/python3.10/site-packages/django/template/base.py", line 961, in render_annotated
    return self.render(context)
  File "/usr/local/lib/python3.10/site-packages/django/template/loader_tags.py", line 159, in render
    return compiled_parent._render(context)
  File "/usr/local/lib/python3.10/site-packages/django/template/base.py", line 163, in _render
    return self.nodelist.render(context)
  File "/usr/local/lib/python3.10/site-packages/django/template/base.py", line 1000, in render
    return SafeString("".join([node.render_annotated(context) for node in self]))
  File "/usr/local/lib/python3.10/site-packages/django/template/base.py", line 1000, in <listcomp>
    return SafeString("".join([node.render_annotated(context) for node in self]))
  File "/usr/local/lib/python3.10/site-packages/django/template/base.py", line 961, in render_annotated
    return self.render(context)
  File "/usr/local/lib/python3.10/site-packages/django/template/loader_tags.py", line 65, in render
    result = block.nodelist.render(context)
  File "/usr/local/lib/python3.10/site-packages/django/template/base.py", line 1000, in render
    return SafeString("".join([node.render_annotated(context) for node in self]))
  File "/usr/local/lib/python3.10/site-packages/django/template/base.py", line 1000, in <listcomp>
    return SafeString("".join([node.render_annotated(context) for node in self]))
  File "/usr/local/lib/python3.10/site-packages/django/template/base.py", line 961, in render_annotated
    return self.render(context)
  File "/usr/local/lib/python3.10/site-packages/django/template/loader_tags.py", line 65, in render
    result = block.nodelist.render(context)
  File "/usr/local/lib/python3.10/site-packages/django/template/base.py", line 1000, in render
    return SafeString("".join([node.render_annotated(context) for node in self]))
  File "/usr/local/lib/python3.10/site-packages/django/template/base.py", line 1000, in <listcomp>
    return SafeString("".join([node.render_annotated(context) for node in self]))
  File "/usr/local/lib/python3.10/site-packages/django/template/base.py", line 961, in render_annotated
    return self.render(context)
  File "/usr/local/lib/python3.10/site-packages/django/contrib/admin/templatetags/base.py", line 45, in render
    return super().render(context)
  File "/usr/local/lib/python3.10/site-packages/django/template/library.py", line 258, in render
    _dict = self.func(*resolved_args, **resolved_kwargs)
  File "/usr/local/lib/python3.10/site-packages/django/contrib/admin/templatetags/admin_list.py", line 343, in result_list
    "results": list(results(cl)),
  File "/usr/local/lib/python3.10/site-packages/django/contrib/admin/templatetags/admin_list.py", line 319, in results
    yield ResultList(None, items_for_result(cl, res, None))
  File "/usr/local/lib/python3.10/site-packages/django/contrib/admin/templatetags/admin_list.py", line 310, in __init__
    super().__init__(*items)
  File "/usr/local/lib/python3.10/site-packages/django/contrib/admin/templatetags/admin_list.py", line 217, in items_for_result
    f, attr, value = lookup_field(field_name, result, cl.model_admin)
  File "/usr/local/lib/python3.10/site-packages/django/contrib/admin/utils.py", line 298, in lookup_field
    value = attr(obj)
  File "/app/accounts/admin.py", line 35, in file_count
    return obj.file_set.count()
  File "/usr/local/lib/python3.10/site-packages/django/db/models/manager.py", line 87, in manager_method
    return getattr(self.get_queryset(), name)(*args, **kwargs)
  File "/usr/local/lib/python3.10/site-packages/django/db/models/query.py", line 618, in count
    return self.query.get_count(using=self.db)
  File "/usr/local/lib/python3.10/site-packages/django/db/models/sql/query.py", line 616, in get_count
    return obj.get_aggregation(using, {"__count": Count("*")})["__count"]
  File "/usr/local/lib/python3.10/site-packages/django/db/models/sql/query.py", line 602, in get_aggregation
    result = compiler.execute_sql(SINGLE)
  File "/usr/local/lib/python3.10/site-packages/django/db/models/sql/compiler.py", line 1562, in execute_sql
    cursor.execute(sql, params)
  File "/usr/local/lib/python3.10/site-packages/django/db/backends/utils.py", line 122, in execute
    return super().execute(sql, params)
  File "/usr/local/lib/python3.10/site-packages/django/db/backends/utils.py", line 79, in execute
    return self._execute_with_wrappers(
  File "/usr/local/lib/python3.10/site-packages/django/db/backends/utils.py", line 92, in _execute_with_wrappers
    return executor(sql, params, many, context)
  File "/usr/local/lib/python3.10/site-packages/django/db/backends/utils.py", line 100, in _execute
    with self.db.wrap_database_errors:
  File "/usr/local/lib/python3.10/site-packages/django/db/utils.py", line 91, in __exit__
    raise dj_exc_value.with_traceback(traceback) from exc_value
  File "/usr/local/lib/python3.10/site-packages/django/db/backends/utils.py", line 105, in _execute
    return self.cursor.execute(sql, params)
django.db.utils.ProgrammingError: relation "storage_file" does not exist
LINE 1: SELECT COUNT(*) AS "__count" FROM "storage_file" WHERE "stor...
                                          ^

2024-11-19 09:35:20,979 ERROR django.server "GET /admin/accounts/user/ HTTP/1.1" 500 416244
2024-11-19 09:35:22,289 INFO django.server "GET /admin/ HTTP/1.1" 200 7533
2024-11-19 09:35:41,887 INFO django.utils.autoreload Watching for file changes with StatReloader
2024-11-19 09:42:05,078 INFO django.utils.autoreload Watching for file changes with StatReloader
2024-11-19 09:43:58,387 WARNING django.request Not Found: /
2024-11-19 09:43:58,387 WARNING django.server "GET / HTTP/1.1" 404 2928
2024-11-19 09:44:01,627 INFO django.server "GET /admin/ HTTP/1.1" 302 0
2024-11-19 09:44:01,649 INFO django.server "GET /admin/login/?next=/admin/ HTTP/1.1" 200 4158
2024-11-19 09:44:05,295 INFO django.server "POST /admin/login/?next=/admin/ HTTP/1.1" 302 0
2024-11-19 09:44:05,322 INFO django.server "GET /admin/ HTTP/1.1" 200 6427
2024-11-19 09:44:07,296 INFO django.server "GET /admin/accounts/user/add/ HTTP/1.1" 200 14744
2024-11-19 09:44:07,350 INFO django.server "GET /admin/jsi18n/ HTTP/1.1" 200 3342
2024-11-19 09:44:07,353 INFO django.server "GET /static/admin/css/widgets.css HTTP/1.1" 200 11800
2024-11-19 09:44:26,632 INFO django.server "POST /admin/accounts/user/add/ HTTP/1.1" 302 0
2024-11-19 09:44:26,666 INFO django.server "GET /admin/accounts/user/2/change/ HTTP/1.1" 200 14293
2024-11-19 09:44:26,733 INFO django.server "GET /admin/jsi18n/ HTTP/1.1" 200 3342
2024-11-19 09:44:38,014 INFO django.server "GET /admin/authtoken/tokenproxy/ HTTP/1.1" 200 7625
2024-11-19 09:44:38,062 INFO django.server "GET /static/admin/css/changelists.css HTTP/1.1" 200 6811
2024-11-19 09:44:39,737 INFO django.server "GET /admin/authtoken/ HTTP/1.1" 200 5089
2024-11-19 09:44:40,863 INFO django.server "GET /admin/authtoken/tokenproxy/add/ HTTP/1.1" 200 9499
2024-11-19 09:44:40,915 INFO django.server "GET /admin/jsi18n/ HTTP/1.1" 200 3342
2024-11-19 09:44:46,338 INFO django.server "POST /admin/authtoken/tokenproxy/add/ HTTP/1.1" 302 0
2024-11-19 09:44:46,364 INFO django.server "GET /admin/authtoken/tokenproxy/ HTTP/1.1" 200 8856
2024-11-19 09:44:47,905 INFO django.server "GET /admin/authtoken/tokenproxy/add/ HTTP/1.1" 200 9499
2024-11-19 09:44:47,960 INFO django.server "GET /admin/jsi18n/ HTTP/1.1" 200 3342
2024-11-19 09:44:49,690 INFO django.server "POST /admin/authtoken/tokenproxy/add/ HTTP/1.1" 302 0
2024-11-19 09:44:49,715 INFO django.server "GET /admin/authtoken/tokenproxy/ HTTP/1.1" 200 9093
2024-11-19 09:44:49,804 WARNING django.request Not Found: /favicon.ico
2024-11-19 09:44:49,804 WARNING django.server "GET /favicon.ico HTTP/1.1" 404 2979
2024-11-19 10:16:24,655 INFO django.utils.autoreload Watching for file changes with StatReloader
2024-11-19 10:22:20,286 INFO django.utils.autoreload Watching for file changes with StatReloader
2024-11-19 10:23:15,033 ERROR django.server "GET /admin/ HTTP/1.1" 500 59
2024-11-19 10:23:15,409 ERROR django.server "GET /favicon.ico HTTP/1.1" 500 59
2024-11-19 10:28:01,867 INFO django.utils.autoreload Watching for file changes with StatReloader
2024-11-19 10:28:11,573 WARNING django.request Not Found: /
2024-11-19 10:28:11,574 WARNING django.server "GET / HTTP/1.1" 404 2928
2024-11-19 10:28:50,479 INFO django.server "GET /admin/ HTTP/1.1" 302 0
2024-11-19 10:28:50,497 INFO django.server "GET /admin/login/?next=/admin/ HTTP/1.1" 200 4158
2024-11-19 10:28:50,547 INFO django.server "GET /static/admin/css/login.css HTTP/1.1" 200 958
2024-11-19 10:28:52,616 INFO django.server "POST /admin/login/?next=/admin/ HTTP/1.1" 302 0
2024-11-19 10:28:52,646 INFO django.server "GET /admin/ HTTP/1.1" 200 6427
2024-11-19 10:28:54,202 INFO django.server "GET /admin/accounts/user/add/ HTTP/1.1" 200 14745
2024-11-19 10:28:54,249 INFO django.server "GET /static/admin/js/prepopulate_init.js HTTP/1.1" 200 586
2024-11-19 10:28:54,259 INFO django.server "GET /admin/jsi18n/ HTTP/1.1" 200 3342
2024-11-19 10:28:54,261 INFO django.server "GET /static/admin/css/widgets.css HTTP/1.1" 200 11800
2024-11-19 10:28:54,300 WARNING django.request Not Found: /favicon.ico
2024-11-19 10:28:54,301 WARNING django.server "GET /favicon.ico HTTP/1.1" 404 2979
2024-11-19 10:29:08,778 INFO django.server "POST /admin/accounts/user/add/ HTTP/1.1" 200 14946
2024-11-19 10:29:08,836 INFO django.server "GET /admin/jsi18n/ HTTP/1.1" 200 3342
2024-11-19 10:29:15,475 INFO django.server "POST /admin/accounts/user/add/ HTTP/1.1" 302 0
2024-11-19 10:29:15,510 INFO django.server "GET /admin/accounts/user/2/change/ HTTP/1.1" 200 14294
2024-11-19 10:29:15,564 INFO django.server "GET /admin/jsi18n/ HTTP/1.1" 200 3342
2024-11-19 10:29:15,588 WARNING django.request Not Found: /favicon.ico
2024-11-19 10:29:15,589 WARNING django.server "GET /favicon.ico HTTP/1.1" 404 2979
2024-11-19 10:29:53,589 INFO django.server "GET /admin/accounts/ HTTP/1.1" 200 5048
2024-11-19 10:29:55,296 INFO django.server "GET /admin/accounts/user/ HTTP/1.1" 200 10865
2024-11-19 10:29:55,352 INFO django.server "GET /admin/jsi18n/ HTTP/1.1" 200 3342
2024-11-19 10:29:55,354 INFO django.server "GET /static/admin/img/icon-no.svg HTTP/1.1" 200 560
2024-11-19 10:29:55,355 INFO django.server "GET /static/admin/img/search.svg HTTP/1.1" 200 458
2024-11-19 10:30:01,520 INFO django.server "GET /admin/authtoken/ HTTP/1.1" 200 5089
2024-11-19 10:30:03,046 INFO django.server "GET /admin/accounts/user/ HTTP/1.1" 200 10865
2024-11-19 10:30:03,971 INFO django.server "GET /admin/authtoken/tokenproxy/ HTTP/1.1" 200 7625
2024-11-19 10:30:04,036 WARNING django.request Not Found: /favicon.ico
2024-11-19 10:30:04,036 WARNING django.server "GET /favicon.ico HTTP/1.1" 404 2979
2024-11-19 10:30:05,121 INFO django.server "GET /admin/authtoken/ HTTP/1.1" 200 5089
2024-11-19 10:30:06,159 INFO django.server "GET /admin/authtoken/tokenproxy/add/ HTTP/1.1" 200 9499
2024-11-19 10:30:06,201 INFO django.server "GET /admin/jsi18n/ HTTP/1.1" 200 3342
2024-11-19 10:30:09,083 INFO django.server "POST /admin/authtoken/tokenproxy/add/ HTTP/1.1" 302 0
2024-11-19 10:30:09,108 INFO django.server "GET /admin/authtoken/tokenproxy/ HTTP/1.1" 200 8857
2024-11-19 10:30:09,178 WARNING django.request Not Found: /favicon.ico
2024-11-19 10:30:09,179 WARNING django.server "GET /favicon.ico HTTP/1.1" 404 2979
2024-11-19 10:30:10,666 INFO django.server "GET /admin/authtoken/tokenproxy/add/ HTTP/1.1" 200 9499
2024-11-19 10:30:10,710 INFO django.server "GET /admin/jsi18n/ HTTP/1.1" 200 3342
2024-11-19 10:30:12,387 INFO django.server "POST /admin/authtoken/tokenproxy/add/ HTTP/1.1" 302 0
2024-11-19 10:30:12,410 INFO django.server "GET /admin/authtoken/tokenproxy/ HTTP/1.1" 200 9095
2024-11-19 10:30:12,469 WARNING django.request Not Found: /favicon.ico
2024-11-19 10:30:12,469 WARNING django.server "GET /favicon.ico HTTP/1.1" 404 2979
2024-11-19 10:30:56,917 INFO django.server "GET /admin/storage/ HTTP/1.1" 200 5037
2024-11-19 10:30:58,582 INFO django.server "GET /admin/ HTTP/1.1" 200 7572
2024-11-19 10:30:59,773 INFO django.server "GET /admin/accounts/user/ HTTP/1.1" 200 10865
2024-11-19 10:30:59,817 INFO django.server "GET /admin/jsi18n/ HTTP/1.1" 200 3342
2024-11-19 10:31:02,398 INFO django.server "GET /admin/accounts/user/?o=5.1 HTTP/1.1" 200 11367
2024-11-19 10:31:02,448 INFO django.server "GET /admin/jsi18n/ HTTP/1.1" 200 3342
2024-11-19 10:31:02,476 WARNING django.request Not Found: /favicon.ico
2024-11-19 10:31:02,476 WARNING django.server "GET /favicon.ico HTTP/1.1" 404 2979
2024-11-19 10:31:02,621 INFO django.server "GET /admin/accounts/user/?o=-5.1 HTTP/1.1" 200 11376
2024-11-19 10:31:02,667 INFO django.server "GET /admin/jsi18n/ HTTP/1.1" 200 3342
2024-11-19 10:31:03,266 INFO django.server "GET /admin/accounts/user/?o=5.1 HTTP/1.1" 200 11367
2024-11-19 10:31:03,315 INFO django.server "GET /admin/jsi18n/ HTTP/1.1" 200 3342
2024-11-19 10:31:04,482 INFO django.server "GET /admin/accounts/user/2/change/?_changelist_filters=o%3D5.1 HTTP/1.1" 200 14161
2024-11-19 10:31:04,528 INFO django.server "GET /admin/jsi18n/ HTTP/1.1" 200 3342
2024-11-19 10:31:06,723 INFO django.server "POST /admin/accounts/user/2/change/?_changelist_filters=o%3D5.1 HTTP/1.1" 302 0
2024-11-19 10:31:06,749 INFO django.server "GET /admin/accounts/user/?o=5.1 HTTP/1.1" 200 11567
2024-11-19 10:31:06,787 INFO django.server "GET /admin/jsi18n/ HTTP/1.1" 200 3342
2024-11-19 10:31:06,813 WARNING django.request Not Found: /favicon.ico
2024-11-19 10:31:06,813 WARNING django.server "GET /favicon.ico HTTP/1.1" 404 2979
2024-11-19 10:31:58,407 WARNING django.request Not Found: /
2024-11-19 10:31:58,407 WARNING django.server "GET / HTTP/1.1" 404 2928
2024-11-19 10:32:03,411 WARNING django.request Method Not Allowed: /login/
2024-11-19 10:32:03,411 WARNING django.server "GET /login/ HTTP/1.1" 405 5582
2024-11-19 10:32:03,452 INFO django.server "GET /static/rest_framework/css/default.css HTTP/1.1" 200 1152
2024-11-19 10:32:25,362 WARNING django.request Not Found: /login/torchhik
2024-11-19 10:32:25,363 WARNING django.server "GET /login/torchhik HTTP/1.1" 404 2988
2024-11-19 10:32:33,966 WARNING django.request Method Not Allowed: /register/
2024-11-19 10:32:33,967 WARNING django.server "GET /register/ HTTP/1.1" 405 5599
2024-11-19 10:32:49,312 WARNING django.request Unauthorized: /api/
2024-11-19 10:32:49,312 WARNING django.server "GET /api/ HTTP/1.1" 401 5019
2024-11-19 10:35:53,193 WARNING django.request Method Not Allowed: /login/
2024-11-19 10:35:53,194 WARNING django.server "GET /login/ HTTP/1.1" 405 5582
2024-11-19 10:36:08,172 INFO django.server "GET /admin/ HTTP/1.1" 200 7921
2024-11-19 10:36:10,624 INFO django.server "GET /admin/accounts/user/ HTTP/1.1" 200 10865
2024-11-19 10:36:10,688 INFO django.server "GET /admin/jsi18n/ HTTP/1.1" 200 3342
2024-11-19 10:36:11,472 INFO django.server "GET /admin/authtoken/tokenproxy/ HTTP/1.1" 200 8857
2024-11-19 10:36:13,252 INFO django.server "GET /admin/storage/ HTTP/1.1" 200 5037
2024-11-19 10:36:15,359 INFO django.server "GET /admin/ HTTP/1.1" 200 7921
2024-11-19 10:36:16,631 INFO django.server "GET /admin/accounts/user/ HTTP/1.1" 200 10865
2024-11-19 10:36:16,690 INFO django.server "GET /admin/jsi18n/ HTTP/1.1" 200 3342
2024-11-19 10:36:19,279 INFO django.server "GET /admin/accounts/user/2/change/ HTTP/1.1" 200 14075
2024-11-19 10:36:19,330 INFO django.server "GET /static/admin/js/change_form.js HTTP/1.1" 200 606
2024-11-19 10:36:19,331 INFO django.server "GET /static/admin/js/prepopulate_init.js HTTP/1.1" 200 586
2024-11-19 10:36:19,336 INFO django.server "GET /admin/jsi18n/ HTTP/1.1" 200 3342
2024-11-19 10:36:20,240 INFO django.server "GET /admin/accounts/user/ HTTP/1.1" 200 10865
2024-11-19 10:36:21,568 INFO django.server "GET /admin/accounts/user/2/change/ HTTP/1.1" 200 14075
2024-11-19 10:36:21,624 INFO django.server "GET /admin/jsi18n/ HTTP/1.1" 200 3342
2024-11-19 10:36:24,090 INFO django.server "POST /admin/accounts/user/2/change/ HTTP/1.1" 302 0
2024-11-19 10:36:24,117 INFO django.server "GET /admin/accounts/user/ HTTP/1.1" 200 11065
2024-11-19 10:36:24,172 INFO django.server "GET /admin/jsi18n/ HTTP/1.1" 200 3342
2024-11-19 10:36:25,318 INFO django.server "GET /admin/accounts/user/?o=-1 HTTP/1.1" 200 10996
2024-11-19 10:36:25,382 INFO django.server "GET /admin/jsi18n/ HTTP/1.1" 200 3342
2024-11-19 10:36:26,188 INFO django.server "GET /admin/accounts/user/2/change/?_changelist_filters=o%3D-1 HTTP/1.1" 200 14158
2024-11-19 10:36:26,255 INFO django.server "GET /admin/jsi18n/ HTTP/1.1" 200 3342
2024-11-19 10:36:46,238 INFO django.server "GET /admin/accounts/user/ HTTP/1.1" 200 10865
2024-11-19 10:36:46,305 INFO django.server "GET /admin/jsi18n/ HTTP/1.1" 200 3342
2024-11-19 10:36:48,494 INFO django.server "GET /admin/accounts/user/add/ HTTP/1.1" 200 14745
2024-11-19 10:36:48,552 INFO django.server "GET /admin/jsi18n/ HTTP/1.1" 200 3342
2024-11-19 10:37:01,220 INFO django.server "POST /admin/accounts/user/add/ HTTP/1.1" 302 0
2024-11-19 10:37:01,253 INFO django.server "GET /admin/accounts/user/3/change/ HTTP/1.1" 200 14299
2024-11-19 10:37:01,341 INFO django.server "GET /admin/jsi18n/ HTTP/1.1" 200 3342
2024-11-19 10:38:02,727 INFO django.server "GET /admin/accounts/user/3/change/ HTTP/1.1" 200 14071
2024-11-19 10:38:02,777 INFO django.server "GET /admin/jsi18n/ HTTP/1.1" 200 3342
2024-11-19 10:38:04,447 INFO django.server "GET /admin/accounts/user/ HTTP/1.1" 200 11404
2024-11-19 10:38:04,508 INFO django.server "GET /admin/jsi18n/ HTTP/1.1" 200 3342
2024-11-19 10:38:08,360 INFO django.server "GET /admin/password_change/ HTTP/1.1" 200 7524
2024-11-19 10:38:10,659 INFO django.server "GET /admin/ HTTP/1.1" 200 8615
2024-11-19 10:38:15,628 INFO django.server "GET /admin/storage/ HTTP/1.1" 200 5037
2024-11-19 10:38:16,930 INFO django.server "GET /admin/ HTTP/1.1" 200 8615
2024-11-19 10:38:57,727 WARNING django.request Not Found: /auth/login
2024-11-19 10:38:57,727 WARNING django.server "GET /auth/login HTTP/1.1" 404 2976
2024-11-19 10:45:57,507 INFO django.utils.autoreload Watching for file changes with StatReloader
2024-11-19 10:46:08,159 WARNING django.request Not Found: /
2024-11-19 10:46:08,160 WARNING django.server "GET / HTTP/1.1" 404 2928
2024-11-19 10:46:11,846 INFO django.server "GET /admin/ HTTP/1.1" 200 8615
2024-11-19 10:46:11,898 INFO django.server "GET /static/admin/js/theme.js HTTP/1.1" 304 0
2024-11-19 10:46:11,900 INFO django.server "GET /static/admin/js/nav_sidebar.js HTTP/1.1" 304 0
2024-11-19 10:46:11,902 INFO django.server "GET /static/admin/css/responsive.css HTTP/1.1" 304 0
2024-11-19 10:46:11,903 INFO django.server "GET /static/admin/css/dashboard.css HTTP/1.1" 304 0
2024-11-19 10:46:11,904 INFO django.server "GET /static/admin/css/dark_mode.css HTTP/1.1" 200 2682
2024-11-19 10:46:11,904 INFO django.server "GET /static/admin/css/nav_sidebar.css HTTP/1.1" 200 2810
2024-11-19 10:46:11,904 INFO django.server "GET /static/admin/css/base.css HTTP/1.1" 200 21544
2024-11-19 10:46:11,951 INFO django.server "GET /static/admin/img/icon-changelink.svg HTTP/1.1" 200 380
2024-11-19 10:46:11,951 INFO django.server "GET /static/admin/img/icon-addlink.svg HTTP/1.1" 200 331
2024-11-19 10:46:18,101 INFO django.server "GET /admin/accounts/user/ HTTP/1.1" 200 11404
2024-11-19 10:46:18,153 INFO django.server "GET /static/admin/js/jquery.init.js HTTP/1.1" 304 0
2024-11-19 10:46:18,153 INFO django.server "GET /static/admin/js/actions.js HTTP/1.1" 304 0
2024-11-19 10:46:18,153 INFO django.server "GET /static/admin/js/core.js HTTP/1.1" 304 0
2024-11-19 10:46:18,153 INFO django.server "GET /static/admin/js/admin/RelatedObjectLookups.js HTTP/1.1" 304 0
2024-11-19 10:46:18,153 INFO django.server "GET /static/admin/js/urlify.js HTTP/1.1" 304 0
2024-11-19 10:46:18,154 INFO django.server "GET /static/admin/js/vendor/jquery/jquery.js HTTP/1.1" 304 0
2024-11-19 10:46:18,156 INFO django.server "GET /static/admin/js/vendor/xregexp/xregexp.js HTTP/1.1" 304 0
2024-11-19 10:46:18,156 INFO django.server "GET /static/admin/js/prepopulate.js HTTP/1.1" 304 0
2024-11-19 10:46:18,157 INFO django.server "GET /static/admin/css/changelists.css HTTP/1.1" 304 0
2024-11-19 10:46:18,159 INFO django.server "GET /static/admin/js/filters.js HTTP/1.1" 304 0
2024-11-19 10:46:18,170 INFO django.server "GET /admin/jsi18n/ HTTP/1.1" 200 3342
2024-11-19 10:46:18,232 INFO django.server "GET /static/admin/img/tooltag-add.svg HTTP/1.1" 200 331
2024-11-19 10:46:27,774 INFO django.server "POST /admin/accounts/user/ HTTP/1.1" 200 7949
2024-11-19 10:46:27,818 INFO django.server "GET /static/admin/js/cancel.js HTTP/1.1" 200 884
2024-11-19 10:46:30,917 INFO django.server "POST /admin/accounts/user/ HTTP/1.1" 302 0
2024-11-19 10:46:30,943 INFO django.server "GET /admin/accounts/user/ HTTP/1.1" 200 10462
2024-11-19 10:46:30,994 INFO django.server "GET /admin/jsi18n/ HTTP/1.1" 200 3342
2024-11-19 10:46:33,469 INFO django.server "GET /admin/accounts/user/add/ HTTP/1.1" 200 14745
2024-11-19 10:46:33,523 INFO django.server "GET /static/admin/css/forms.css HTTP/1.1" 200 9048
2024-11-19 10:46:33,532 INFO django.server "GET /admin/jsi18n/ HTTP/1.1" 200 3342
2024-11-19 10:46:33,537 INFO django.server "GET /static/admin/css/widgets.css HTTP/1.1" 200 11800
2024-11-19 10:46:41,229 INFO django.server "POST /admin/accounts/user/add/ HTTP/1.1" 302 0
2024-11-19 10:46:41,263 INFO django.server "GET /admin/accounts/user/4/change/ HTTP/1.1" 200 14294
2024-11-19 10:46:41,336 INFO django.server "GET /admin/jsi18n/ HTTP/1.1" 200 3342
2024-11-19 10:49:36,061 INFO django.utils.autoreload Watching for file changes with StatReloader
2024-11-19 10:49:44,861 INFO django.server "GET /admin/accounts/user/4/change/ HTTP/1.1" 200 14067
2024-11-19 10:49:44,897 INFO django.server "GET /static/admin/js/inlines.js HTTP/1.1" 304 0
2024-11-19 10:49:44,898 INFO django.server "GET /static/admin/js/change_form.js HTTP/1.1" 304 0
2024-11-19 10:49:44,899 INFO django.server "GET /static/admin/js/prepopulate_init.js HTTP/1.1" 304 0
2024-11-19 10:49:44,900 INFO django.server "GET /static/admin/css/forms.css HTTP/1.1" 304 0
2024-11-19 10:49:44,905 INFO django.server "GET /admin/jsi18n/ HTTP/1.1" 200 3342
2024-11-19 10:49:44,911 INFO django.server "GET /static/admin/css/widgets.css HTTP/1.1" 200 11800
2024-11-19 10:49:44,941 WARNING django.request Not Found: /favicon.ico
2024-11-19 10:49:44,942 WARNING django.server "GET /favicon.ico HTTP/1.1" 404 2979
2024-11-19 10:49:47,108 INFO django.server "GET /admin/accounts/user/ HTTP/1.1" 200 10865
2024-11-19 10:49:47,170 INFO django.server "GET /admin/jsi18n/ HTTP/1.1" 200 3342
2024-11-19 10:49:47,186 INFO django.server "GET /static/admin/img/icon-yes.svg HTTP/1.1" 200 436
2024-11-19 10:49:47,258 WARNING django.request Not Found: /favicon.ico
2024-11-19 10:49:47,258 WARNING django.server "GET /favicon.ico HTTP/1.1" 404 2979
2024-11-19 10:50:01,468 INFO django.server "POST /admin/accounts/user/ HTTP/1.1" 200 7710
2024-11-19 10:50:01,538 WARNING django.request Not Found: /favicon.ico
2024-11-19 10:50:01,538 WARNING django.server "GET /favicon.ico HTTP/1.1" 404 2979
2024-11-19 10:50:02,395 INFO django.server "POST /admin/accounts/user/ HTTP/1.1" 302 0
2024-11-19 10:50:02,423 INFO django.server "GET /admin/accounts/user/ HTTP/1.1" 200 10461
2024-11-19 10:50:02,479 INFO django.server "GET /admin/jsi18n/ HTTP/1.1" 200 3342
2024-11-19 10:50:04,384 INFO django.server "GET /admin/accounts/user/add/ HTTP/1.1" 200 14745
2024-11-19 10:50:04,439 INFO django.server "GET /admin/jsi18n/ HTTP/1.1" 200 3342
2024-11-19 10:50:04,474 WARNING django.request Not Found: /favicon.ico
2024-11-19 10:50:04,475 WARNING django.server "GET /favicon.ico HTTP/1.1" 404 2979
2024-11-19 10:50:11,254 INFO django.server "POST /admin/accounts/user/add/ HTTP/1.1" 302 0
2024-11-19 10:50:11,290 INFO django.server "GET /admin/accounts/user/5/change/ HTTP/1.1" 200 14294
2024-11-19 10:50:11,367 INFO django.server "GET /admin/jsi18n/ HTTP/1.1" 200 3342
2024-11-19 11:50:24,045 INFO django.utils.autoreload Watching for file changes with StatReloader
2024-11-19 11:52:47,489 INFO django.server "OPTIONS /login/ HTTP/1.1" 200 0
2024-11-19 11:52:47,832 ERROR django.request Internal Server Error: /login/
Traceback (most recent call last):
  File "/app/accounts/views.py", line 48, in login_view
    token = Token.objects.get(user=authenticated_user)
  File "/usr/local/lib/python3.10/site-packages/django/db/models/manager.py", line 87, in manager_method
    return getattr(self.get_queryset(), name)(*args, **kwargs)
  File "/usr/local/lib/python3.10/site-packages/django/db/models/query.py", line 647, in get
    raise self.model.DoesNotExist(
rest_framework.authtoken.models.Token.DoesNotExist: Token matching query does not exist.

During handling of the above exception, another exception occurred:

Traceback (most recent call last):
  File "/usr/local/lib/python3.10/site-packages/django/db/backends/utils.py", line 105, in _execute
    return self.cursor.execute(sql, params)
psycopg2.errors.NotNullViolation: null value in column "user_id" of relation "authtoken_token" violates not-null constraint
DETAIL:  Failing row contains (ad880fbdf8d036521c3aef108ce8f169ef80a948, 2024-11-19 11:52:47.787846+00, null).


The above exception was the direct cause of the following exception:

Traceback (most recent call last):
  File "/usr/local/lib/python3.10/site-packages/django/core/handlers/exception.py", line 55, in inner
    response = get_response(request)
  File "/usr/local/lib/python3.10/site-packages/django/core/handlers/base.py", line 197, in _get_response
    response = wrapped_callback(request, *callback_args, **callback_kwargs)
  File "/usr/local/lib/python3.10/site-packages/django/views/decorators/csrf.py", line 65, in _view_wrapper
    return view_func(request, *args, **kwargs)
  File "/usr/local/lib/python3.10/site-packages/django/views/generic/base.py", line 104, in view
    return self.dispatch(request, *args, **kwargs)
  File "/usr/local/lib/python3.10/site-packages/rest_framework/views.py", line 509, in dispatch
    response = self.handle_exception(exc)
  File "/usr/local/lib/python3.10/site-packages/rest_framework/views.py", line 469, in handle_exception
    self.raise_uncaught_exception(exc)
  File "/usr/local/lib/python3.10/site-packages/rest_framework/views.py", line 480, in raise_uncaught_exception
    raise exc
  File "/usr/local/lib/python3.10/site-packages/rest_framework/views.py", line 506, in dispatch
    response = handler(request, *args, **kwargs)
  File "/usr/local/lib/python3.10/site-packages/rest_framework/decorators.py", line 50, in handler
    return func(*args, **kwargs)
  File "/app/accounts/views.py", line 50, in login_view
    token = Token.objects.create(user=authenticated_user)
  File "/usr/local/lib/python3.10/site-packages/django/db/models/manager.py", line 87, in manager_method
    return getattr(self.get_queryset(), name)(*args, **kwargs)
  File "/usr/local/lib/python3.10/site-packages/django/db/models/query.py", line 677, in create
    obj.save(force_insert=True, using=self.db)
  File "/usr/local/lib/python3.10/site-packages/rest_framework/authtoken/models.py", line 33, in save
    return super().save(*args, **kwargs)
  File "/usr/local/lib/python3.10/site-packages/django/db/models/base.py", line 814, in save
    self.save_base(
  File "/usr/local/lib/python3.10/site-packages/django/db/models/base.py", line 901, in save_base
    updated = self._save_table(
  File "/usr/local/lib/python3.10/site-packages/django/db/models/base.py", line 1059, in _save_table
    results = self._do_insert(
  File "/usr/local/lib/python3.10/site-packages/django/db/models/base.py", line 1100, in _do_insert
    return manager._insert(
  File "/usr/local/lib/python3.10/site-packages/django/db/models/manager.py", line 87, in manager_method
    return getattr(self.get_queryset(), name)(*args, **kwargs)
  File "/usr/local/lib/python3.10/site-packages/django/db/models/query.py", line 1845, in _insert
    return query.get_compiler(using=using).execute_sql(returning_fields)
  File "/usr/local/lib/python3.10/site-packages/django/db/models/sql/compiler.py", line 1822, in execute_sql
    cursor.execute(sql, params)
  File "/usr/local/lib/python3.10/site-packages/django/db/backends/utils.py", line 122, in execute
    return super().execute(sql, params)
  File "/usr/local/lib/python3.10/site-packages/django/db/backends/utils.py", line 79, in execute
    return self._execute_with_wrappers(
  File "/usr/local/lib/python3.10/site-packages/django/db/backends/utils.py", line 92, in _execute_with_wrappers
    return executor(sql, params, many, context)
  File "/usr/local/lib/python3.10/site-packages/django/db/backends/utils.py", line 100, in _execute
    with self.db.wrap_database_errors:
  File "/usr/local/lib/python3.10/site-packages/django/db/utils.py", line 91, in __exit__
    raise dj_exc_value.with_traceback(traceback) from exc_value
  File "/usr/local/lib/python3.10/site-packages/django/db/backends/utils.py", line 105, in _execute
    return self.cursor.execute(sql, params)
django.db.utils.IntegrityError: null value in column "user_id" of relation "authtoken_token" violates not-null constraint
DETAIL:  Failing row contains (ad880fbdf8d036521c3aef108ce8f169ef80a948, 2024-11-19 11:52:47.787846+00, null).

2024-11-19 11:52:47,834 ERROR django.server "POST /login/ HTTP/1.1" 500 188375
2024-11-19 11:52:58,213 INFO django.server "OPTIONS /register/ HTTP/1.1" 200 0
2024-11-19 11:52:58,500 INFO django.server "POST /register/ HTTP/1.1" 201 141
2024-11-19 11:52:58,578 INFO django.server "OPTIONS /api/users/6/ HTTP/1.1" 200 0
2024-11-19 11:52:58,581 INFO django.server "OPTIONS /api/files/ HTTP/1.1" 200 0
2024-11-19 11:52:58,581 INFO django.server "OPTIONS /api/users/ HTTP/1.1" 200 0
2024-11-19 11:52:58,593 INFO django.server "GET /api/users/6/ HTTP/1.1" 200 40
2024-11-19 11:52:58,595 INFO django.server "GET /api/users/ HTTP/1.1" 200 42
2024-11-19 11:52:58,601 INFO django.server "GET /api/files/ HTTP/1.1" 200 2
2024-11-19 11:52:58,614 INFO django.server "GET /api/users/6/ HTTP/1.1" 200 40
2024-11-19 11:52:58,614 INFO django.server "GET /api/users/ HTTP/1.1" 200 42
2024-11-19 11:52:58,617 INFO django.server "GET /api/files/ HTTP/1.1" 200 2
2024-11-19 11:53:13,817 WARNING django.request Bad Request: /api/users/6/
2024-11-19 11:53:13,817 WARNING django.server "PATCH /api/users/6/ HTTP/1.1" 400 147
2024-11-19 11:53:21,640 INFO django.server "PATCH /api/users/6/ HTTP/1.1" 200 43
2024-11-19 11:53:23,229 INFO django.server "GET /api/users/6/ HTTP/1.1" 200 40
2024-11-19 11:53:23,230 INFO django.server "GET /api/users/ HTTP/1.1" 200 42
2024-11-19 11:53:23,236 INFO django.server "GET /api/files/ HTTP/1.1" 200 2
2024-11-19 11:53:23,248 INFO django.server "GET /api/users/6/ HTTP/1.1" 200 40
2024-11-19 11:53:23,252 INFO django.server "GET /api/users/ HTTP/1.1" 200 42
2024-11-19 11:53:23,259 INFO django.server "GET /api/files/ HTTP/1.1" 200 2
2024-11-19 11:53:37,544 INFO django.server "OPTIONS /logout/ HTTP/1.1" 200 0
2024-11-19 11:53:37,555 INFO django.server "GET /logout/ HTTP/1.1" 200 73
2024-11-19 11:53:45,860 ERROR django.request Internal Server Error: /login/
Traceback (most recent call last):
  File "/app/accounts/views.py", line 48, in login_view
    token = Token.objects.get(user=authenticated_user)
  File "/usr/local/lib/python3.10/site-packages/django/db/models/manager.py", line 87, in manager_method
    return getattr(self.get_queryset(), name)(*args, **kwargs)
  File "/usr/local/lib/python3.10/site-packages/django/db/models/query.py", line 647, in get
    raise self.model.DoesNotExist(
rest_framework.authtoken.models.Token.DoesNotExist: Token matching query does not exist.

During handling of the above exception, another exception occurred:

Traceback (most recent call last):
  File "/usr/local/lib/python3.10/site-packages/django/db/backends/utils.py", line 105, in _execute
    return self.cursor.execute(sql, params)
psycopg2.errors.NotNullViolation: null value in column "user_id" of relation "authtoken_token" violates not-null constraint
DETAIL:  Failing row contains (75c54b6f7cde5bb362528c65077663511b1130f0, 2024-11-19 11:53:45.829616+00, null).


The above exception was the direct cause of the following exception:

Traceback (most recent call last):
  File "/usr/local/lib/python3.10/site-packages/django/core/handlers/exception.py", line 55, in inner
    response = get_response(request)
  File "/usr/local/lib/python3.10/site-packages/django/core/handlers/base.py", line 197, in _get_response
    response = wrapped_callback(request, *callback_args, **callback_kwargs)
  File "/usr/local/lib/python3.10/site-packages/django/views/decorators/csrf.py", line 65, in _view_wrapper
    return view_func(request, *args, **kwargs)
  File "/usr/local/lib/python3.10/site-packages/django/views/generic/base.py", line 104, in view
    return self.dispatch(request, *args, **kwargs)
  File "/usr/local/lib/python3.10/site-packages/rest_framework/views.py", line 509, in dispatch
    response = self.handle_exception(exc)
  File "/usr/local/lib/python3.10/site-packages/rest_framework/views.py", line 469, in handle_exception
    self.raise_uncaught_exception(exc)
  File "/usr/local/lib/python3.10/site-packages/rest_framework/views.py", line 480, in raise_uncaught_exception
    raise exc
  File "/usr/local/lib/python3.10/site-packages/rest_framework/views.py", line 506, in dispatch
    response = handler(request, *args, **kwargs)
  File "/usr/local/lib/python3.10/site-packages/rest_framework/decorators.py", line 50, in handler
    return func(*args, **kwargs)
  File "/app/accounts/views.py", line 50, in login_view
    token = Token.objects.create(user=authenticated_user)
  File "/usr/local/lib/python3.10/site-packages/django/db/models/manager.py", line 87, in manager_method
    return getattr(self.get_queryset(), name)(*args, **kwargs)
  File "/usr/local/lib/python3.10/site-packages/django/db/models/query.py", line 677, in create
    obj.save(force_insert=True, using=self.db)
  File "/usr/local/lib/python3.10/site-packages/rest_framework/authtoken/models.py", line 33, in save
    return super().save(*args, **kwargs)
  File "/usr/local/lib/python3.10/site-packages/django/db/models/base.py", line 814, in save
    self.save_base(
  File "/usr/local/lib/python3.10/site-packages/django/db/models/base.py", line 901, in save_base
    updated = self._save_table(
  File "/usr/local/lib/python3.10/site-packages/django/db/models/base.py", line 1059, in _save_table
    results = self._do_insert(
  File "/usr/local/lib/python3.10/site-packages/django/db/models/base.py", line 1100, in _do_insert
    return manager._insert(
  File "/usr/local/lib/python3.10/site-packages/django/db/models/manager.py", line 87, in manager_method
    return getattr(self.get_queryset(), name)(*args, **kwargs)
  File "/usr/local/lib/python3.10/site-packages/django/db/models/query.py", line 1845, in _insert
    return query.get_compiler(using=using).execute_sql(returning_fields)
  File "/usr/local/lib/python3.10/site-packages/django/db/models/sql/compiler.py", line 1822, in execute_sql
    cursor.execute(sql, params)
  File "/usr/local/lib/python3.10/site-packages/django/db/backends/utils.py", line 122, in execute
    return super().execute(sql, params)
  File "/usr/local/lib/python3.10/site-packages/django/db/backends/utils.py", line 79, in execute
    return self._execute_with_wrappers(
  File "/usr/local/lib/python3.10/site-packages/django/db/backends/utils.py", line 92, in _execute_with_wrappers
    return executor(sql, params, many, context)
  File "/usr/local/lib/python3.10/site-packages/django/db/backends/utils.py", line 100, in _execute
    with self.db.wrap_database_errors:
  File "/usr/local/lib/python3.10/site-packages/django/db/utils.py", line 91, in __exit__
    raise dj_exc_value.with_traceback(traceback) from exc_value
  File "/usr/local/lib/python3.10/site-packages/django/db/backends/utils.py", line 105, in _execute
    return self.cursor.execute(sql, params)
django.db.utils.IntegrityError: null value in column "user_id" of relation "authtoken_token" violates not-null constraint
DETAIL:  Failing row contains (75c54b6f7cde5bb362528c65077663511b1130f0, 2024-11-19 11:53:45.829616+00, null).

2024-11-19 11:53:45,861 ERROR django.server "POST /login/ HTTP/1.1" 500 188552
2024-11-19 11:53:47,078 ERROR django.request Internal Server Error: /register/
Traceback (most recent call last):
  File "/usr/local/lib/python3.10/site-packages/django/core/handlers/exception.py", line 55, in inner
    response = get_response(request)
  File "/usr/local/lib/python3.10/site-packages/django/core/handlers/base.py", line 197, in _get_response
    response = wrapped_callback(request, *callback_args, **callback_kwargs)
  File "/usr/local/lib/python3.10/site-packages/django/views/decorators/csrf.py", line 65, in _view_wrapper
    return view_func(request, *args, **kwargs)
  File "/usr/local/lib/python3.10/site-packages/django/views/generic/base.py", line 104, in view
    return self.dispatch(request, *args, **kwargs)
  File "/usr/local/lib/python3.10/site-packages/rest_framework/views.py", line 509, in dispatch
    response = self.handle_exception(exc)
  File "/usr/local/lib/python3.10/site-packages/rest_framework/views.py", line 469, in handle_exception
    self.raise_uncaught_exception(exc)
  File "/usr/local/lib/python3.10/site-packages/rest_framework/views.py", line 480, in raise_uncaught_exception
    raise exc
  File "/usr/local/lib/python3.10/site-packages/rest_framework/views.py", line 506, in dispatch
    response = handler(request, *args, **kwargs)
  File "/usr/local/lib/python3.10/site-packages/rest_framework/decorators.py", line 50, in handler
    return func(*args, **kwargs)
  File "/app/accounts/views.py", line 36, in signup_view
    response_message = f"User '{user.username}' was not created. Error: {serializer.errors}."
UnboundLocalError: local variable 'user' referenced before assignment
2024-11-19 11:53:47,079 ERROR django.server "POST /register/ HTTP/1.1" 500 91297
2024-11-19 11:53:47,669 ERROR django.request Internal Server Error: /register/
Traceback (most recent call last):
  File "/usr/local/lib/python3.10/site-packages/django/core/handlers/exception.py", line 55, in inner
    response = get_response(request)
  File "/usr/local/lib/python3.10/site-packages/django/core/handlers/base.py", line 197, in _get_response
    response = wrapped_callback(request, *callback_args, **callback_kwargs)
  File "/usr/local/lib/python3.10/site-packages/django/views/decorators/csrf.py", line 65, in _view_wrapper
    return view_func(request, *args, **kwargs)
  File "/usr/local/lib/python3.10/site-packages/django/views/generic/base.py", line 104, in view
    return self.dispatch(request, *args, **kwargs)
  File "/usr/local/lib/python3.10/site-packages/rest_framework/views.py", line 509, in dispatch
    response = self.handle_exception(exc)
  File "/usr/local/lib/python3.10/site-packages/rest_framework/views.py", line 469, in handle_exception
    self.raise_uncaught_exception(exc)
  File "/usr/local/lib/python3.10/site-packages/rest_framework/views.py", line 480, in raise_uncaught_exception
    raise exc
  File "/usr/local/lib/python3.10/site-packages/rest_framework/views.py", line 506, in dispatch
    response = handler(request, *args, **kwargs)
  File "/usr/local/lib/python3.10/site-packages/rest_framework/decorators.py", line 50, in handler
    return func(*args, **kwargs)
  File "/app/accounts/views.py", line 36, in signup_view
    response_message = f"User '{user.username}' was not created. Error: {serializer.errors}."
UnboundLocalError: local variable 'user' referenced before assignment
2024-11-19 11:53:47,670 ERROR django.server "POST /register/ HTTP/1.1" 500 91297
2024-11-19 11:53:48,233 ERROR django.request Internal Server Error: /register/
Traceback (most recent call last):
  File "/usr/local/lib/python3.10/site-packages/django/core/handlers/exception.py", line 55, in inner
    response = get_response(request)
  File "/usr/local/lib/python3.10/site-packages/django/core/handlers/base.py", line 197, in _get_response
    response = wrapped_callback(request, *callback_args, **callback_kwargs)
  File "/usr/local/lib/python3.10/site-packages/django/views/decorators/csrf.py", line 65, in _view_wrapper
    return view_func(request, *args, **kwargs)
  File "/usr/local/lib/python3.10/site-packages/django/views/generic/base.py", line 104, in view
    return self.dispatch(request, *args, **kwargs)
  File "/usr/local/lib/python3.10/site-packages/rest_framework/views.py", line 509, in dispatch
    response = self.handle_exception(exc)
  File "/usr/local/lib/python3.10/site-packages/rest_framework/views.py", line 469, in handle_exception
    self.raise_uncaught_exception(exc)
  File "/usr/local/lib/python3.10/site-packages/rest_framework/views.py", line 480, in raise_uncaught_exception
    raise exc
  File "/usr/local/lib/python3.10/site-packages/rest_framework/views.py", line 506, in dispatch
    response = handler(request, *args, **kwargs)
  File "/usr/local/lib/python3.10/site-packages/rest_framework/decorators.py", line 50, in handler
    return func(*args, **kwargs)
  File "/app/accounts/views.py", line 36, in signup_view
    response_message = f"User '{user.username}' was not created. Error: {serializer.errors}."
UnboundLocalError: local variable 'user' referenced before assignment
2024-11-19 11:53:48,234 ERROR django.server "POST /register/ HTTP/1.1" 500 91297
2024-11-19 11:53:49,997 INFO django.server "POST /register/ HTTP/1.1" 201 155
2024-11-19 11:53:50,068 INFO django.server "OPTIONS /api/users/7/ HTTP/1.1" 200 0
2024-11-19 11:53:50,077 INFO django.server "GET /api/files/ HTTP/1.1" 200 2
2024-11-19 11:53:50,078 INFO django.server "GET /api/users/ HTTP/1.1" 200 49
2024-11-19 11:53:50,085 INFO django.server "GET /api/users/7/ HTTP/1.1" 200 47
2024-11-19 11:53:50,091 INFO django.server "GET /api/files/ HTTP/1.1" 200 2
2024-11-19 11:53:50,096 INFO django.server "GET /api/users/ HTTP/1.1" 200 49
2024-11-19 11:53:50,100 INFO django.server "GET /api/users/7/ HTTP/1.1" 200 47
2024-11-19 11:53:58,277 WARNING django.request Bad Request: /api/users/7/
2024-11-19 11:53:58,277 WARNING django.server "PATCH /api/users/7/ HTTP/1.1" 400 154
2024-11-19 11:54:03,882 INFO django.server "GET /api/users/7/ HTTP/1.1" 200 47
2024-11-19 11:54:03,882 INFO django.server "GET /api/files/ HTTP/1.1" 200 2
2024-11-19 11:54:03,890 INFO django.server "GET /api/users/ HTTP/1.1" 200 49
2024-11-19 11:54:03,903 INFO django.server "GET /api/users/7/ HTTP/1.1" 200 47
2024-11-19 11:54:03,903 INFO django.server "GET /api/files/ HTTP/1.1" 200 2
2024-11-19 11:54:03,914 INFO django.server "GET /api/users/ HTTP/1.1" 200 49
2024-11-19 11:54:04,794 INFO django.server "GET /api/users/7/ HTTP/1.1" 200 47
2024-11-19 11:54:04,794 INFO django.server "GET /api/files/ HTTP/1.1" 200 2
2024-11-19 11:54:04,800 INFO django.server "GET /api/users/ HTTP/1.1" 200 49
2024-11-19 11:54:04,821 INFO django.server "GET /api/files/ HTTP/1.1" 200 2
2024-11-19 11:54:04,821 INFO django.server "GET /api/users/7/ HTTP/1.1" 200 47
2024-11-19 11:54:04,826 INFO django.server "GET /api/users/ HTTP/1.1" 200 49
2024-11-19 11:55:37,054 INFO django.server "OPTIONS /login/ HTTP/1.1" 200 0
2024-11-19 11:55:37,358 ERROR django.request Internal Server Error: /login/
Traceback (most recent call last):
  File "/app/accounts/views.py", line 48, in login_view
    token = Token.objects.get(user=authenticated_user)
  File "/usr/local/lib/python3.10/site-packages/django/db/models/manager.py", line 87, in manager_method
    return getattr(self.get_queryset(), name)(*args, **kwargs)
  File "/usr/local/lib/python3.10/site-packages/django/db/models/query.py", line 647, in get
    raise self.model.DoesNotExist(
rest_framework.authtoken.models.Token.DoesNotExist: Token matching query does not exist.

During handling of the above exception, another exception occurred:

Traceback (most recent call last):
  File "/usr/local/lib/python3.10/site-packages/django/db/backends/utils.py", line 105, in _execute
    return self.cursor.execute(sql, params)
psycopg2.errors.NotNullViolation: null value in column "user_id" of relation "authtoken_token" violates not-null constraint
DETAIL:  Failing row contains (25708ddbe6c58e19ea27bccbb219f92422a9ea67, 2024-11-19 11:55:37.326586+00, null).


The above exception was the direct cause of the following exception:

Traceback (most recent call last):
  File "/usr/local/lib/python3.10/site-packages/django/core/handlers/exception.py", line 55, in inner
    response = get_response(request)
  File "/usr/local/lib/python3.10/site-packages/django/core/handlers/base.py", line 197, in _get_response
    response = wrapped_callback(request, *callback_args, **callback_kwargs)
  File "/usr/local/lib/python3.10/site-packages/django/views/decorators/csrf.py", line 65, in _view_wrapper
    return view_func(request, *args, **kwargs)
  File "/usr/local/lib/python3.10/site-packages/django/views/generic/base.py", line 104, in view
    return self.dispatch(request, *args, **kwargs)
  File "/usr/local/lib/python3.10/site-packages/rest_framework/views.py", line 509, in dispatch
    response = self.handle_exception(exc)
  File "/usr/local/lib/python3.10/site-packages/rest_framework/views.py", line 469, in handle_exception
    self.raise_uncaught_exception(exc)
  File "/usr/local/lib/python3.10/site-packages/rest_framework/views.py", line 480, in raise_uncaught_exception
    raise exc
  File "/usr/local/lib/python3.10/site-packages/rest_framework/views.py", line 506, in dispatch
    response = handler(request, *args, **kwargs)
  File "/usr/local/lib/python3.10/site-packages/rest_framework/decorators.py", line 50, in handler
    return func(*args, **kwargs)
  File "/app/accounts/views.py", line 50, in login_view
    token = Token.objects.create(user=authenticated_user)
  File "/usr/local/lib/python3.10/site-packages/django/db/models/manager.py", line 87, in manager_method
    return getattr(self.get_queryset(), name)(*args, **kwargs)
  File "/usr/local/lib/python3.10/site-packages/django/db/models/query.py", line 677, in create
    obj.save(force_insert=True, using=self.db)
  File "/usr/local/lib/python3.10/site-packages/rest_framework/authtoken/models.py", line 33, in save
    return super().save(*args, **kwargs)
  File "/usr/local/lib/python3.10/site-packages/django/db/models/base.py", line 814, in save
    self.save_base(
  File "/usr/local/lib/python3.10/site-packages/django/db/models/base.py", line 901, in save_base
    updated = self._save_table(
  File "/usr/local/lib/python3.10/site-packages/django/db/models/base.py", line 1059, in _save_table
    results = self._do_insert(
  File "/usr/local/lib/python3.10/site-packages/django/db/models/base.py", line 1100, in _do_insert
    return manager._insert(
  File "/usr/local/lib/python3.10/site-packages/django/db/models/manager.py", line 87, in manager_method
    return getattr(self.get_queryset(), name)(*args, **kwargs)
  File "/usr/local/lib/python3.10/site-packages/django/db/models/query.py", line 1845, in _insert
    return query.get_compiler(using=using).execute_sql(returning_fields)
  File "/usr/local/lib/python3.10/site-packages/django/db/models/sql/compiler.py", line 1822, in execute_sql
    cursor.execute(sql, params)
  File "/usr/local/lib/python3.10/site-packages/django/db/backends/utils.py", line 122, in execute
    return super().execute(sql, params)
  File "/usr/local/lib/python3.10/site-packages/django/db/backends/utils.py", line 79, in execute
    return self._execute_with_wrappers(
  File "/usr/local/lib/python3.10/site-packages/django/db/backends/utils.py", line 92, in _execute_with_wrappers
    return executor(sql, params, many, context)
  File "/usr/local/lib/python3.10/site-packages/django/db/backends/utils.py", line 100, in _execute
    with self.db.wrap_database_errors:
  File "/usr/local/lib/python3.10/site-packages/django/db/utils.py", line 91, in __exit__
    raise dj_exc_value.with_traceback(traceback) from exc_value
  File "/usr/local/lib/python3.10/site-packages/django/db/backends/utils.py", line 105, in _execute
    return self.cursor.execute(sql, params)
django.db.utils.IntegrityError: null value in column "user_id" of relation "authtoken_token" violates not-null constraint
DETAIL:  Failing row contains (25708ddbe6c58e19ea27bccbb219f92422a9ea67, 2024-11-19 11:55:37.326586+00, null).

2024-11-19 11:55:37,359 ERROR django.server "POST /login/ HTTP/1.1" 500 188742
2024-11-19 11:56:03,333 INFO django.server "OPTIONS /register/ HTTP/1.1" 200 0
2024-11-19 11:56:03,623 INFO django.server "POST /register/ HTTP/1.1" 201 153
2024-11-19 11:56:03,677 INFO django.server "OPTIONS /api/users/8/ HTTP/1.1" 200 0
2024-11-19 11:56:03,679 INFO django.server "OPTIONS /api/files/ HTTP/1.1" 200 0
2024-11-19 11:56:03,681 INFO django.server "OPTIONS /api/users/ HTTP/1.1" 200 0
2024-11-19 11:56:03,694 INFO django.server "GET /api/users/8/ HTTP/1.1" 200 46
2024-11-19 11:56:03,700 INFO django.server "GET /api/files/ HTTP/1.1" 200 2
2024-11-19 11:56:03,706 INFO django.server "GET /api/users/ HTTP/1.1" 200 48
2024-11-19 11:56:28,518 WARNING django.request Not Found: /
2024-11-19 11:56:28,518 WARNING django.server "GET / HTTP/1.1" 404 2928
2024-11-19 11:56:31,670 INFO django.server "GET /admin/ HTTP/1.1" 200 9872
2024-11-19 11:56:31,732 INFO django.server "GET /static/admin/img/icon-addlink.svg HTTP/1.1" 200 331
2024-11-19 11:56:31,732 INFO django.server "GET /static/admin/img/icon-deletelink.svg HTTP/1.1" 200 392
2024-11-19 11:56:31,733 INFO django.server "GET /static/admin/img/icon-changelink.svg HTTP/1.1" 200 380
2024-11-19 11:56:35,269 INFO django.server "GET /admin/accounts/user/ HTTP/1.1" 200 12496
2024-11-19 11:56:35,321 INFO django.server "GET /admin/jsi18n/ HTTP/1.1" 200 3342
2024-11-19 11:56:35,324 INFO django.server "GET /static/admin/img/icon-no.svg HTTP/1.1" 200 560
2024-11-19 11:56:35,324 INFO django.server "GET /static/admin/img/search.svg HTTP/1.1" 200 458
2024-11-19 11:56:35,338 INFO django.server "GET /static/admin/img/icon-yes.svg HTTP/1.1" 200 436
2024-11-19 11:56:35,346 INFO django.server "GET /static/admin/img/tooltag-add.svg HTTP/1.1" 200 331
2024-11-19 11:56:35,346 INFO django.server "GET /static/admin/img/sorting-icons.svg HTTP/1.1" 200 1097
2024-11-19 11:56:47,362 INFO django.server "POST /admin/accounts/user/ HTTP/1.1" 200 8162
2024-11-19 11:56:47,398 INFO django.server "GET /static/admin/js/cancel.js HTTP/1.1" 200 884
2024-11-19 11:56:48,552 INFO django.server "POST /admin/accounts/user/ HTTP/1.1" 302 0
2024-11-19 11:56:48,580 INFO django.server "GET /admin/accounts/user/ HTTP/1.1" 200 11010
2024-11-19 11:56:48,627 INFO django.server "GET /admin/jsi18n/ HTTP/1.1" 200 3342
2024-11-19 11:56:51,038 INFO django.server "GET /admin/accounts/user/?o=5.1 HTTP/1.1" 200 11377
2024-11-19 11:56:51,090 INFO django.server "GET /admin/jsi18n/ HTTP/1.1" 200 3342
2024-11-19 11:56:53,121 INFO django.server "GET /admin/accounts/user/ HTTP/1.1" 200 10875
2024-11-19 11:57:09,910 INFO django.server "GET /admin/accounts/user/1/change/ HTTP/1.1" 200 14063
2024-11-19 11:57:09,954 INFO django.server "GET /static/admin/js/prepopulate_init.js HTTP/1.1" 200 586
2024-11-19 11:57:09,961 INFO django.server "GET /admin/jsi18n/ HTTP/1.1" 200 3342
2024-11-19 11:57:09,964 INFO django.server "GET /static/admin/css/widgets.css HTTP/1.1" 200 11800
2024-11-19 11:57:17,322 INFO django.server "GET /admin/accounts/user/ HTTP/1.1" 200 10875
2024-11-19 12:12:21,648 INFO django.utils.autoreload Watching for file changes with StatReloader
2024-11-19 12:20:53,558 INFO django.utils.autoreload Watching for file changes with StatReloader
2024-11-19 12:21:06,865 INFO django.server "OPTIONS /login/ HTTP/1.1" 200 0
2024-11-19 12:21:07,198 ERROR django.request Internal Server Error: /login/
Traceback (most recent call last):
  File "/app/accounts/views.py", line 48, in login_view
    token = Token.objects.get(user=authenticated_user)
  File "/usr/local/lib/python3.10/site-packages/django/db/models/manager.py", line 87, in manager_method
    return getattr(self.get_queryset(), name)(*args, **kwargs)
  File "/usr/local/lib/python3.10/site-packages/django/db/models/query.py", line 647, in get
    raise self.model.DoesNotExist(
rest_framework.authtoken.models.Token.DoesNotExist: Token matching query does not exist.

During handling of the above exception, another exception occurred:

Traceback (most recent call last):
  File "/usr/local/lib/python3.10/site-packages/django/db/backends/utils.py", line 105, in _execute
    return self.cursor.execute(sql, params)
psycopg2.errors.NotNullViolation: null value in column "user_id" of relation "authtoken_token" violates not-null constraint
DETAIL:  Failing row contains (5d37b479e07ca1f6935fcd6b753cabe6ccb412b0, 2024-11-19 12:21:07.149938+00, null).


The above exception was the direct cause of the following exception:

Traceback (most recent call last):
  File "/usr/local/lib/python3.10/site-packages/django/core/handlers/exception.py", line 55, in inner
    response = get_response(request)
  File "/usr/local/lib/python3.10/site-packages/django/core/handlers/base.py", line 197, in _get_response
    response = wrapped_callback(request, *callback_args, **callback_kwargs)
  File "/usr/local/lib/python3.10/site-packages/django/views/decorators/csrf.py", line 65, in _view_wrapper
    return view_func(request, *args, **kwargs)
  File "/usr/local/lib/python3.10/site-packages/django/views/generic/base.py", line 104, in view
    return self.dispatch(request, *args, **kwargs)
  File "/usr/local/lib/python3.10/site-packages/rest_framework/views.py", line 509, in dispatch
    response = self.handle_exception(exc)
  File "/usr/local/lib/python3.10/site-packages/rest_framework/views.py", line 469, in handle_exception
    self.raise_uncaught_exception(exc)
  File "/usr/local/lib/python3.10/site-packages/rest_framework/views.py", line 480, in raise_uncaught_exception
    raise exc
  File "/usr/local/lib/python3.10/site-packages/rest_framework/views.py", line 506, in dispatch
    response = handler(request, *args, **kwargs)
  File "/usr/local/lib/python3.10/site-packages/rest_framework/decorators.py", line 50, in handler
    return func(*args, **kwargs)
  File "/app/accounts/views.py", line 50, in login_view
    token = Token.objects.create(user=authenticated_user)
  File "/usr/local/lib/python3.10/site-packages/django/db/models/manager.py", line 87, in manager_method
    return getattr(self.get_queryset(), name)(*args, **kwargs)
  File "/usr/local/lib/python3.10/site-packages/django/db/models/query.py", line 677, in create
    obj.save(force_insert=True, using=self.db)
  File "/usr/local/lib/python3.10/site-packages/rest_framework/authtoken/models.py", line 33, in save
    return super().save(*args, **kwargs)
  File "/usr/local/lib/python3.10/site-packages/django/db/models/base.py", line 814, in save
    self.save_base(
  File "/usr/local/lib/python3.10/site-packages/django/db/models/base.py", line 901, in save_base
    updated = self._save_table(
  File "/usr/local/lib/python3.10/site-packages/django/db/models/base.py", line 1059, in _save_table
    results = self._do_insert(
  File "/usr/local/lib/python3.10/site-packages/django/db/models/base.py", line 1100, in _do_insert
    return manager._insert(
  File "/usr/local/lib/python3.10/site-packages/django/db/models/manager.py", line 87, in manager_method
    return getattr(self.get_queryset(), name)(*args, **kwargs)
  File "/usr/local/lib/python3.10/site-packages/django/db/models/query.py", line 1845, in _insert
    return query.get_compiler(using=using).execute_sql(returning_fields)
  File "/usr/local/lib/python3.10/site-packages/django/db/models/sql/compiler.py", line 1822, in execute_sql
    cursor.execute(sql, params)
  File "/usr/local/lib/python3.10/site-packages/django/db/backends/utils.py", line 122, in execute
    return super().execute(sql, params)
  File "/usr/local/lib/python3.10/site-packages/django/db/backends/utils.py", line 79, in execute
    return self._execute_with_wrappers(
  File "/usr/local/lib/python3.10/site-packages/django/db/backends/utils.py", line 92, in _execute_with_wrappers
    return executor(sql, params, many, context)
  File "/usr/local/lib/python3.10/site-packages/django/db/backends/utils.py", line 100, in _execute
    with self.db.wrap_database_errors:
  File "/usr/local/lib/python3.10/site-packages/django/db/utils.py", line 91, in __exit__
    raise dj_exc_value.with_traceback(traceback) from exc_value
  File "/usr/local/lib/python3.10/site-packages/django/db/backends/utils.py", line 105, in _execute
    return self.cursor.execute(sql, params)
django.db.utils.IntegrityError: null value in column "user_id" of relation "authtoken_token" violates not-null constraint
DETAIL:  Failing row contains (5d37b479e07ca1f6935fcd6b753cabe6ccb412b0, 2024-11-19 12:21:07.149938+00, null).

2024-11-19 12:21:07,201 ERROR django.server "POST /login/ HTTP/1.1" 500 188372
2024-11-19 12:21:08,212 INFO django.server "OPTIONS /register/ HTTP/1.1" 200 0
2024-11-19 12:21:08,502 INFO django.server "POST /register/ HTTP/1.1" 201 153
2024-11-19 12:21:08,560 INFO django.server "OPTIONS /api/users/1/ HTTP/1.1" 200 0
2024-11-19 12:21:08,560 INFO django.server "OPTIONS /api/files/ HTTP/1.1" 200 0
2024-11-19 12:21:08,561 INFO django.server "OPTIONS /api/users/ HTTP/1.1" 200 0
2024-11-19 12:21:08,580 INFO django.server "GET /api/users/ HTTP/1.1" 200 48
2024-11-19 12:21:08,580 INFO django.server "GET /api/users/1/ HTTP/1.1" 200 46
2024-11-19 12:21:08,584 INFO django.server "GET /api/files/ HTTP/1.1" 200 2
2024-11-19 12:21:30,519 INFO django.server "PATCH /api/users/1/ HTTP/1.1" 200 61
2024-11-19 12:22:02,283 INFO django.server "OPTIONS /api/files/ HTTP/1.1" 200 0
2024-11-19 12:22:02,312 INFO django.server "POST /api/files/ HTTP/1.1" 201 281
2024-11-19 12:22:02,331 INFO django.server "GET /api/files/ HTTP/1.1" 200 283
2024-11-19 12:24:28,394 WARNING django.request Not Found: /
2024-11-19 12:24:28,395 WARNING django.server "GET / HTTP/1.1" 404 2928
2024-11-19 12:24:32,205 INFO django.server "GET /admin/ HTTP/1.1" 302 0
2024-11-19 12:24:32,225 INFO django.server "GET /admin/login/?next=/admin/ HTTP/1.1" 200 4158
2024-11-19 12:24:32,275 INFO django.server "GET /static/admin/css/login.css HTTP/1.1" 200 958
2024-11-19 12:24:36,537 INFO django.server "POST /admin/login/?next=/admin/ HTTP/1.1" 302 0
2024-11-19 12:24:36,560 INFO django.server "GET /admin/ HTTP/1.1" 200 6427
2024-11-19 12:24:38,468 INFO django.server "GET /admin/accounts/user/ HTTP/1.1" 200 10875
2024-11-19 12:24:38,523 INFO django.server "GET /admin/jsi18n/ HTTP/1.1" 200 3342
2024-11-19 12:24:38,545 WARNING django.request Not Found: /favicon.ico
2024-11-19 12:24:38,546 WARNING django.server "GET /favicon.ico HTTP/1.1" 404 2979
2024-11-19 12:24:41,977 INFO django.server "OPTIONS /logout/ HTTP/1.1" 200 0
2024-11-19 12:24:41,989 INFO django.server "GET /logout/ HTTP/1.1" 200 85
2024-11-19 12:24:45,938 INFO django.server "POST /login/ HTTP/1.1" 200 139
2024-11-19 12:24:45,991 INFO django.server "OPTIONS /api/users/2/ HTTP/1.1" 200 0
2024-11-19 12:24:46,002 INFO django.server "GET /api/files/ HTTP/1.1" 200 283
2024-11-19 12:24:46,002 INFO django.server "GET /api/users/ HTTP/1.1" 200 250
2024-11-19 12:24:46,008 INFO django.server "GET /api/users/2/ HTTP/1.1" 200 113
2024-11-19 12:24:49,027 INFO django.server "GET /api/users/2/ HTTP/1.1" 200 113
2024-11-19 12:24:49,041 INFO django.server "GET /api/users/2/ HTTP/1.1" 200 113
2024-11-19 12:24:49,108 INFO django.server "GET /api/users/ HTTP/1.1" 200 250
2024-11-19 12:25:01,313 INFO django.server "GET /api/files/ HTTP/1.1" 200 283
2024-11-19 12:25:01,315 INFO django.server "GET /api/users/ HTTP/1.1" 200 250
